Workbook

Sheet Data
A1: No. | B1: Name | C1: Safety | H1: Comfort Level | M1: Accessibility | R1: Walking Distance | W1: Heritage & Cultural Value | AB1: Scenery & Aesthetic | AG1: Total | AH1: Time window | AI1: Entrance fee | AJ1: Stay duration | AK1: Walking distance | AL1: Google Satisfaction score | AM1: Trip.com Satisfaction score | AN1: Wongnai Satisfaction score | AO1: Latitude | AP1: Longitude
A2: No | C2: S1 | D2: S2 | E2: S3 | F2: S4 | G2: S5 | H2: C1 | I2: C2 | J2: C3 | K2: C4 | L2: C5 | M2: A1 | N2: A2 | O2: A3 | P2: A4 | Q2: A5 | R2: W1 | S2: W2 | T2: W3 | U2: W4 | V2: W5 | W2: H1 | X2: H2 | Y2: H3 | Z2: H4 | AA2: H5 | AB2: SC1 | AC2: SC2 | AD2: SC3 | AE2: SC4 | AF2: SC5
A3: 1 | B3: Wat Phra That Doi Suthep | C3: 0 | D3: 1 | E3: 1 | F3: 0 | G3: 1 | H3: 1 | I3: 1 | J3: 1 | K3: 1 | L3: 1 | M3: 0 | N3: 1 | O3: 1 | P3: 0 | Q3: 0 | R3: 0 | S3: 1 | T3: 0 | U3: 1 | V3: 1 | W3: 1 | X3: 1 | Y3: 0 | Z3: 0 | AA3: 1 | AB3: 1 | AC3: 1 | AD3: 1 | AE3: 1 | AF3: 1 | AG3: =SUM(C3:AF3) -> 21 | AH3: 06:00-20:00 | AI3: 20 | AJ3: 1.5 hr | AK3: 500 m | AL3: 4.7 | AM3: 4.7 | AN3: 4.5 | AO3: 18.805 | AP3: 98.9216
A4: 2 | B4: Wat Chedi Luang | C4: 1 | D4: 1 | E4: 1 | F4: 1 | G4: 1 | H4: 1 | I4: 1 | J4: 1 | K4: 1 | L4: 1 | M4: 1 | N4: 1 | O4: 1 | P4: 1 | Q4: 1 | R4: 1 | S4: 1 | T4: 1 | U4: 1 | V4: 1 | W4: 1 | X4: 1 | Y4: 0 | Z4: 1 | AA4: 1 | AB4: 1 | AC4: 1 | AD4: 0 | AE4: 0 | AF4: 1 | AG4: =SUM(C4:AF4) -> 27 | AH4: 05:00-22:00 | AI4: 0 | AJ4: 1 hr | AK4: 300 m | AL4: 4.7 | AM4: 4.8 | AN4: 4.5 | AO4: 18.787 | AP4: 98.9866
A5: 3 | B5: Wat Phra Singh | C5: 1 | D5: 1 | E5: 1 | F5: 1 | G5: 1 | H5: 1 | I5: 1 | J5: 1 | K5: 1 | L5: 1 | M5: 1 | N5: 1 | O5: 1 | P5: 1 | Q5: 1 | R5: 1 | S5: 1 | T5: 1 | U5: 1 | V5: 1 | W5: 1 | X5: 1 | Y5: 0 | Z5: 1 | AA5: 1 | AB5: 1 | AC5: 1 | AD5: 0 | AE5: 0 | AF5: 1 | AG5: =SUM(C5:AF5) -> 27 | AH5: 05:30-19:30 | AI5: 0 | AJ5: 1 hr | AK5: 250 m | AL5: 4.7 | AM5: 4.7 | AN5: 4.6 | AO5: 18.7885 | AP5: 98.982
A6: 4 | B6: Wat Umong | C6: 1 | D6: 1 | E6: 1 | F6: 0 | G6: 1 | H6: 1 | I6: 1 | J6: 1 | K6: 1 | L6: 1 | M6: 0 | N6: 0 | O6: 1 | P6: 0 | Q6: 0 | R6: 1 | S6: 1 | T6: 0 | U6: 1 | V6: 0 | W6: 1 | X6: 1 | Y6: 0 | Z6: 1 | AA6: 1 | AB6: 1 | AC6: 1 | AD6: 1 | AE6: 0 | AF6: 1 | AG6: =SUM(C6:AF6) -> 21 | AH6: 05:00-20:00 | AI6: 0 | AJ6: 1 hr | AK6: 400 m | AL6: 4.6 | AM6: 4.7 | AN6: 4.3 | AO6: 18.7827 | AP6: 98.9521
A7: 5 | B7: Wat Chiang Man | C7: 1 | D7: 1 | E7: 1 | F7: 1 | G7: 1 | H7: 1 | I7: 1 | J7: 1 | K7: 1 | L7: 1 | M7: 1 | N7: 1 | O7: 1 | P7: 1 | Q7: 1 | R7: 1 | S7: 1 | T7: 1 | U7: 1 | V7: 1 | W7: 1 | X7: 1 | Y7: 0 | Z7: 1 | AA7: 1 | AB7: 1 | AC7: 1 | AD7: 0 | AE7: 0 | AF7: 1 | AG7: =SUM(C7:AF7) -> 27 | AH7: 06:00-18:00 | AI7: 0 | AJ7: 1 hr | AK7: 300 m | AL7: 4.6 | AM7: 4.6 | AN7: 4.1 | AO7: 18.7938 | AP7: 98.9893
A8: 6 | B8: Wat Suan Dok | C8: 1 | D8: 1 | E8: 1 | F8: 1 | G8: 1 | H8: 1 | I8: 1 | J8: 1 | K8: 1 | L8: 1 | M8: 1 | N8: 1 | O8: 1 | P8: 1 | Q8: 1 | R8: 1 | S8: 1 | T8: 1 | U8: 1 | V8: 1 | W8: 1 | X8: 1 | Y8: 1 | Z8: 1 | AA8: 1 | AB8: 1 | AC8: 1 | AD8: 0 | AE8: 1 | AF8: 1 | AG8: =SUM(C8:AF8) -> 29 | AH8: 06:00-18:00 | AI8: 0 | AJ8: 1 hr | AK8: 350 m | AL8: 4.6 | AM8: 4.6 | AN8: 4.3 | AO8: 18.7882 | AP8: 98.9678
A9: 7 | B9: Wat Lok Moli | C9: 1 | D9: 1 | E9: 1 | F9: 0 | G9: 1 | H9: 1 | I9: 1 | J9: 1 | K9: 1 | L9: 1 | M9: 0 | N9: 1 | O9: 0 | P9: 1 | Q9: 0 | R9: 1 | S9: 1 | T9: 1 | U9: 1 | V9: 0 | W9: 1 | X9: 1 | Y9: 0 | Z9: 1 | AA9: 1 | AB9: 1 | AC9: 1 | AD9: 0 | AE9: 0 | AF9: 1 | AG9: =SUM(C9:AF9) -> 22 | AH9: 08:00-17:30 | AI9: 0 | AJ9: 45 min | AK9: 300 m | AL9: 4.7 | AM9: 4.8 | AN9: 4.4 | AO9: 18.786 | AP9: 98.9826
A10: 8 | B10: Wat Sri Suphan (Silver Temple) | C10: 1 | D10: 1 | E10: 1 | F10: 0 | G10: 1 | H10: 0 | I10: 1 | J10: 1 | K10: 1 | L10: 1 | M10: 0 | N10: 0 | O10: 0 | P10: 0 | Q10: 0 | R10: 1 | S10: 0 | T10: 1 | U10: 0 | V10: 0 | W10: 1 | X10: 1 | Y10: 1 | Z10: 1 | AA10: 1 | AB10: 1 | AC10: 1 | AD10: 0 | AE10: 0 | AF10: 1 | AG10: =SUM(C10:AF10) -> 18 | AH10: 06:00-18:00 | AI10: 0 | AJ10: 1 hr | AK10: 300 m | AL10: 4.5 | AM10: 5 | AN10: 4.3 | AO10: 18.7787 | AP10: 98.9837
A11: 9 | B11: Wat Buppharam | C11: 0 | D11: 1 | E11: 1 | F11: 1 | G11: 1 | H11: 1 | I11: 1 | J11: 1 | K11: 1 | L11: 1 | M11: 0 | N11: 0 | O11: 0 | P11: 1 | Q11: 0 | R11: 1 | S11: 1 | T11: 1 | U11: 1 | V11: 0 | W11: 1 | X11: 1 | Y11: 0 | Z11: 1 | AA11: 1 | AB11: 1 | AC11: 1 | AD11: 0 | AE11: 0 | AF11: 1 | AG11: =SUM(C11:AF11) -> 21 | AH11: 08:00-18:00 | AI11: 0 | AJ11: 45 min | AK11: 250 m | AL11: 4.5 | AM11: 4.5 | AN11: 3.8 | AO11: 18.788 | AP11: 98.9983
A12: 10 | B12: Wat Ket Karam | C12: 1 | D12: 1 | E12: 1 | F12: 1 | G12: 1 | H12: 1 | I12: 1 | J12: 1 | K12: 1 | L12: 1 | M12: 0 | N12: 1 | O12: 1 | P12: 0 | Q12: 0 | R12: 1 | S12: 1 | T12: 1 | U12: 1 | V12: 1 | W12: 1 | X12: 1 | Y12: 0 | Z12: 0 | AA12: 0 | AB12: 1 | AC12: 1 | AD12: 0 | AE12: 0 | AF12: 1 | AG12: =SUM(C12:AF12) -> 22 | AH12: 06:00-18:00 | AI12: 0 | AJ12: 45 min | AK12: 250 m | AL12: 4.6 | AM12: 4.9 | AN12: 4.2 | AO12: 18.7924 | AP12: 99.0034
A13: 11 | B13: Chiang Mai City Arts & Cultural Centre | C13: 1 | D13: 1 | E13: 1 | F13: 1 | G13: 1 | H13: 1 | I13: 1 | J13: 1 | K13: 1 | L13: 1 | M13: 1 | N13: 1 | O13: 1 | P13: 1 | Q13: 1 | R13: 1 | S13: 1 | T13: 1 | U13: 1 | V13: 1 | W13: 1 | X13: 1 | Y13: 0 | Z13: 1 | AA13: 1 | AB13: 1 | AC13: 1 | AD13: 0 | AE13: 0 | AF13: 1 | AG13: =SUM(C13:AF13) -> 27 | AH13: 08:30-16:30 | AI13: 90 | AJ13: 1.5 hr | AK13: 300 m | AL13: 4.5 | AM13: 4.2 | AN13: 4.1 | AO13: 18.7889 | AP13: 98.9908
A14: 12 | B14: Lanna Folklife Museum | C14: 1 | D14: 1 | E14: 1 | F14: 1 | G14: 1 | H14: 1 | I14: 1 | J14: 1 | K14: 1 | L14: 1 | M14: 1 | N14: 1 | O14: 1 | P14: 1 | Q14: 1 | R14: 1 | S14: 1 | T14: 1 | U14: 1 | V14: 1 | W14: 1 | X14: 1 | Y14: 0 | Z14: 1 | AA14: 1 | AB14: 1 | AC14: 1 | AD14: 0 | AE14: 0 | AF14: 1 | AG14: =SUM(C14:AF14) -> 27 | AH14: 08:30-16:30 | AI14: 20 | AJ14: 1.5 hr | AK14: 300 m | AL14: 4.3 | AM14: 4.3 | AN14: 4.6 | AO14: 18.7902 | AP14: 98.9884
A15: 13 | B15: Chiang Mai National Museum | C15: 1 | D15: 1 | E15: 1 | F15: 1 | G15: 1 | H15: 1 | I15: 1 | J15: 1 | K15: 1 | L15: 1 | M15: 1 | N15: 1 | O15: 1 | P15: 0 | Q15: 1 | R15: 1 | S15: 1 | T15: 1 | U15: 1 | V15: 1 | W15: 1 | X15: 1 | Y15: 0 | Z15: 1 | AA15: 1 | AB15: 1 | AC15: 1 | AD15: 0 | AE15: 0 | AF15: 1 | AG15: =SUM(C15:AF15) -> 26 | AH15: 09:00-16:00 | AI15: 20 | AJ15: 1 hr | AK15: 200 m | AL15: 4.2 | AM15: 4.4 | AN15: 3.6 | AO15: 18.8112 | AP15: 98.9764
A16: 14 | B16: Highland People Discovery Museum | C16: 1 | D16: 1 | E16: 1 | F16: 0 | G16: 1 | H16: 1 | I16: 1 | J16: 1 | K16: 1 | L16: 1 | M16: 1 | N16: 0 | O16: 1 | P16: 0 | Q16: 0 | R16: 1 | S16: 1 | T16: 1 | U16: 1 | V16: 1 | W16: 1 | X16: 1 | Y16: 0 | Z16: 1 | AA16: 1 | AB16: 1 | AC16: 1 | AD16: 1 | AE16: 0 | AF16: 1 | AG16: =SUM(C16:AF16) -> 24 | AH16: 08:30-16:00 | AI16: 0 | AJ16: 1 hr | AK16: 200 m | AL16: 4.3 | AM16: 4.6 | AO16: 18.8214 | AP16: 98.9747
A17: 15 | B17: MAIIAM Contemporary Art Museum | C17: 1 | D17: 1 | E17: 1 | F17: 0 | G17: 1 | H17: 1 | I17: 1 | J17: 1 | K17: 1 | L17: 1 | M17: 1 | N17: 1 | O17: 1 | P17: 0 | Q17: 1 | R17: 1 | S17: 0 | T17: 1 | U17: 1 | V17: 1 | W17: 0 | X17: 0 | Y17: 0 | Z17: 1 | AA17: 1 | AB17: 1 | AC17: 1 | AD17: 0 | AE17: 0 | AF17: 0 | AG17: =SUM(C17:AF17) -> 21 | AH17: 10:00-18:00 | AI17: 150 | AJ17: 1.5 hr | AK17: 300 m | AL17: 4.4 | AM17: 4.8 | AN17: 4 | AO17: 18.7572 | AP17: 99.0937
A18: 16 | B18: Art in Paradise 3D Museum | C18: 1 | D18: 1 | E18: 1 | F18: 1 | G18: 1 | H18: 0 | I18: 1 | J18: 1 | K18: 1 | L18: 1 | M18: 1 | N18: 1 | O18: 1 | P18: 1 | Q18: 1 | R18: 1 | S18: 0 | T18: 1 | U18: 1 | V18: 1 | W18: 0 | X18: 0 | Y18: 0 | Z18: 0 | AA18: 0 | AB18: 1 | AC18: 0 | AD18: 0 | AE18: 0 | AF18: 0 | AG18: =SUM(C18:AF18) -> 19 | AH18: 09:00-21:00 | AI18: 200 | AJ18: 2 hr | AK18: 500 m | AL18: 4.5 | AM18: 4.7 | AN18: 4 | AO18: 18.7828 | AP18: 99.0003
A19: 17 | B19: Chiang Mai Historical Centre | C19: 1 | D19: 1 | E19: 1 | F19: 1 | G19: 1 | H19: 1 | I19: 1 | J19: 1 | K19: 1 | L19: 1 | M19: 1 | N19: 1 | O19: 1 | P19: 1 | Q19: 1 | R19: 1 | S19: 1 | T19: 1 | U19: 1 | V19: 1 | W19: 1 | X19: 1 | Y19: 0 | Z19: 1 | AA19: 1 | AB19: 1 | AC19: 1 | AD19: 0 | AE19: 0 | AF19: 1 | AG19: =SUM(C19:AF19) -> 27 | AH19: 08:30-17:00 | AI19: 20 | AJ19: 1 hr | AK19: 200 m | AL19: 4.2 | AM19: 5 | AN19: 4.4 | AO19: 18.7902 | AP19: 98.9863
A20: 18 | B20: Museum of World Insects and Natural Wonders | C20: 0 | D20: 1 | E20: 1 | F20: 0 | G20: 1 | H20: 0 | I20: 1 | J20: 1 | K20: 0 | L20: 0 | M20: 0 | N20: 0 | O20: 0 | P20: 0 | Q20: 0 | R20: 1 | S20: 0 | T20: 1 | U20: 1 | V20: 1 | W20: 0 | X20: 0 | Y20: 0 | Z20: 0 | AA20: 1 | AB20: 0 | AC20: 0 | AD20: 0 | AE20: 0 | AF20: 0 | AG20: =SUM(C20:AF20) -> 10 | AH20: 10:00-15:00 | AI20: 200 | AJ20: 1 hr | AK20: 150 m | AL20: 4.3 | AM20: 4.3 | AO20: 18.7961 | AP20: 98.9706
A21: 19 | B21: Dara Pirom Palace Museum | C21: 1 | D21: 1 | E21: 1 | F21: 0 | G21: 1 | H21: 1 | I21: 1 | J21: 1 | K21: 1 | L21: 1 | M21: 0 | N21: 0 | O21: 0 | P21: 0 | Q21: 0 | R21: 1 | S21: 1 | T21: 1 | U21: 1 | V21: 1 | W21: 1 | X21: 1 | Y21: 0 | Z21: 1 | AA21: 1 | AB21: 1 | AC21: 1 | AD21: 1 | AE21: 0 | AF21: 1 | AG21: =SUM(C21:AF21) -> 22 | AH21: 09:00-17:00 | AI21: 20 | AJ21: 1 hr | AK21: 200 m | AL21: 4.7 | AM21: 5 | AN21: 4.2 | AO21: 18.931 | AP21: 98.892
A22: 20 | B22: Tribal Museum (Highland People Discovery) | C22: 1 | D22: 1 | E22: 1 | F22: 0 | G22: 1 | H22: 1 | I22: 1 | J22: 1 | K22: 1 | L22: 1 | M22: 1 | N22: 0 | O22: 1 | P22: 0 | Q22: 0 | R22: 1 | S22: 1 | T22: 1 | U22: 1 | V22: 1 | W22: 1 | X22: 1 | Y22: 0 | Z22: 1 | AA22: 1 | AB22: 1 | AC22: 1 | AD22: 1 | AE22: 0 | AF22: 1 | AG22: =SUM(C22:AF22) -> 24 | AH22: 09:00-16:00 | AI22: 0 | AJ22: 1 hr | AK22: 200 m | AL22: 3.6 | AO22: 18.8214 | AP22: 98.9747
A23: 21 | B23: Elephant Nature Park | C23: 1 | D23: 1 | E23: 1 | F23: 0 | G23: 0 | H23: 1 | I23: 1 | J23: 1 | K23: 1 | L23: 1 | M23: 0 | N23: 0 | O23: 1 | P23: 0 | Q23: 0 | R23: 0 | S23: 1 | T23: 0 | U23: 1 | V23: 0 | W23: 0 | X23: 1 | Y23: 0 | Z23: 1 | AA23: 1 | AB23: 1 | AC23: 1 | AD23: 1 | AE23: 0 | AF23: 1 | AG23: =SUM(C23:AF23) -> 18 | AH23: 08:00-17:00 | AI23: 0 | AJ23: 5 hr | AK23: 2.0 km | AL23: 4.8 | AM23: 4.5 | AO23: 18.8853 | AP23: 99.0008
A24: 22 | B24: Chiang Mai Zoo | C24: 1 | D24: 1 | E24: 1 | F24: 0 | G24: 1 | H24: 1 | I24: 1 | J24: 0 | K24: 1 | L24: 1 | M24: 0 | N24: 1 | O24: 1 | P24: 1 | Q24: 1 | R24: 0 | S24: 1 | T24: 0 | U24: 1 | V24: 1 | W24: 0 | X24: 0 | Y24: 0 | Z24: 1 | AA24: 1 | AB24: 1 | AC24: 1 | AD24: 1 | AE24: 0 | AF24: 0 | AG24: =SUM(C24:AF24) -> 20 | AH24: 08:00-17:00 | AI24: 0 | AJ24: 3 hr | AK24: 1.5 km | AL24: 3.9 | AM24: 4.5 | AN24: 4.1 | AO24: 18.8106 | AP24: 98.9479
A25: 23 | B25: Chiang Mai Night Safari | C25: 1 | D25: 1 | E25: 1 | F25: 1 | G25: 1 | H25: 1 | I25: 1 | J25: 0 | K25: 1 | L25: 1 | M25: 1 | N25: 1 | O25: 1 | P25: 0 | Q25: 1 | R25: 1 | S25: 1 | T25: 1 | U25: 0 | V25: 1 | W25: 0 | X25: 0 | Y25: 0 | Z25: 1 | AA25: 0 | AB25: 1 | AC25: 1 | AD25: 0 | AE25: 0 | AF25: 0 | AG25: =SUM(C25:AF25) -> 20 | AH25: 11:00-22:00 | AI25: 150 | AJ25: 2.5 hr | AK25: 1.2 km | AL25: 4.3 | AM25: 4.6 | AN25: 4.2 | AO25: 18.7422 | AP25: 98.9172
A26: 24 | B26: Tiger Kingdom Chiang Mai | C26: 1 | D26: 1 | E26: 1 | F26: 0 | G26: 1 | H26: 1 | I26: 1 | J26: 0 | K26: 1 | L26: 1 | M26: 1 | N26: 1 | O26: 1 | P26: 0 | Q26: 0 | R26: 1 | S26: 1 | T26: 1 | U26: 1 | V26: 1 | W26: 0 | X26: 1 | Y26: 0 | Z26: 0 | AA26: 0 | AB26: 1 | AC26: 1 | AD26: 1 | AE26: 0 | AF26: 0 | AG26: =SUM(C26:AF26) -> 20 | AH26: 09:00-17:00 | AI26: 320 | AJ26: 1.5 hr | AK26: 0.5 km | AL26: 4 | AM26: 4.5 | AO26: 18.9246 | AP26: 98.932
A27: 25 | B27: Baan Chang Elephant Park | C27: 0 | D27: 1 | E27: 1 | F27: 0 | G27: 0 | H27: 0 | I27: 0 | J27: 1 | K27: 1 | L27: 1 | M27: 0 | N27: 0 | O27: 0 | P27: 0 | Q27: 0 | R27: 0 | S27: 0 | T27: 0 | U27: 1 | V27: 0 | W27: 0 | X27: 1 | Y27: 0 | Z27: 0 | AA27: 1 | AB27: 1 | AC27: 1 | AD27: 1 | AE27: 1 | AF27: 1 | AG27: =SUM(C27:AF27) -> 13 | AH27: 07:00-17:00 | AI27: 2900 | AJ27: 5 hr | AK27: 2.0 km | AL27: 4.7 | AO27: 18.9333 | AP27: 98.9
A28: 26 | B28: Patara Elephant Farm | C28: 0 | D28: 1 | E28: 1 | F28: 0 | G28: 0 | H28: 0 | I28: 0 | J28: 1 | K28: 1 | L28: 1 | M28: 0 | N28: 0 | O28: 0 | P28: 0 | Q28: 0 | R28: 0 | S28: 0 | T28: 0 | U28: 1 | V28: 0 | W28: 0 | X28: 1 | Y28: 0 | Z28: 0 | AA28: 1 | AB28: 1 | AC28: 1 | AD28: 1 | AE28: 1 | AF28: 1 | AG28: =SUM(C28:AF28) -> 13 | AH28: 08:00-18:00 | AI28: 3200 | AJ28: 6 hr | AK28: 2.5 km | AL28: 4.4 | AO28: 18.7781 | AP28: 98.8163
A29: 27 | B29: Doi Inthanon National Park | C29: 0 | D29: 1 | E29: 1 | F29: 0 | G29: 0 | H29: 0 | I29: 0 | J29: 1 | K29: 1 | L29: 1 | M29: 0 | N29: 0 | O29: 1 | P29: 0 | Q29: 0 | R29: 0 | S29: 0 | T29: 0 | U29: 1 | V29: 0 | W29: 1 | X29: 0 | Y29: 0 | Z29: 1 | AA29: 1 | AB29: 1 | AC29: 1 | AD29: 1 | AE29: 1 | AF29: 1 | AG29: =SUM(C29:AF29) -> 15 | AH29: 06:00-18:00 | AI29: 50 | AJ29: 4 hr | AK29: 3.0 km | AL29: 4.7 | AM29: 4.9 | AN29: 4.5 | AO29: 18.5886 | AP29: 98.487
A30: 28 | B30: Queen Sirikit Botanical Garden | C30: 1 | D30: 1 | E30: 1 | F30: 0 | G30: 1 | H30: 1 | I30: 1 | J30: 1 | K30: 1 | L30: 1 | M30: 0 | N30: 0 | O30: 1 | P30: 0 | Q30: 0 | R30: 0 | S30: 1 | T30: 0 | U30: 1 | V30: 1 | W30: 1 | X30: 0 | Y30: 0 | Z30: 1 | AA30: 1 | AB30: 1 | AC30: 1 | AD30: 1 | AE30: 0 | AF30: 1 | AG30: =SUM(C30:AF30) -> 20 | AH30: 08:30-16:30 | AI30: 0 | AJ30: 2 hr | AK30: 1.5 km | AL30: 4.6 | AM30: 4.7 | AN30: 4.3 | AO30: 18.9114 | AP30: 98.8646
A31: 29 | B31: Tweechol Botanic Garden | C31: 1 | D31: 1 | E31: 1 | F31: 1 | G31: 1 | H31: 1 | I31: 1 | J31: 1 | K31: 1 | L31: 1 | M31: 1 | N31: 1 | O31: 1 | P31: 0 | Q31: 1 | R31: 1 | S31: 1 | T31: 1 | U31: 1 | V31: 1 | W31: 0 | X31: 0 | Y31: 0 | Z31: 1 | AA31: 1 | AB31: 1 | AC31: 1 | AD31: 1 | AE31: 0 | AF31: 1 | AG31: =SUM(C31:AF31) -> 25 | AH31: 08:30-17:00 | AI31: 86 | AJ31: 2 hr | AK31: 1.0 km | AL31: 4.5 | AM31: 4.8 | AN31: 4.2 | AO31: 18.8251 | AP31: 99.0765
A32: 30 | B32: Mon Cham | C32: 0 | D32: 1 | E32: 1 | F32: 0 | G32: 0 | H32: 0 | I32: 0 | J32: 1 | K32: 0 | L32: 1 | M32: 0 | N32: 0 | O32: 0 | P32: 0 | Q32: 0 | R32: 0 | S32: 0 | T32: 0 | U32: 0 | V32: 0 | W32: 0 | X32: 1 | Y32: 0 | Z32: 0 | AA32: 0 | AB32: 1 | AC32: 1 | AD32: 1 | AE32: 1 | AF32: 1 | AG32: =SUM(C32:AF32) -> 10 | AH32: 00:00-24:00 | AI32: 0 | AJ32: 3 hr | AK32: 2.0 km | AL32: 4.4 | AN32: 4.1 | AO32: 18.9333 | AP32: 98.8
A33: 31 | B33: Warorot Market (Kad Luang) | C33: 0 | D33: 0 | E33: 0 | F33: 1 | G33: 0 | H33: 0 | I33: 1 | J33: 0 | K33: 0 | L33: 0 | M33: 0 | N33: 0 | O33: 0 | P33: 1 | Q33: 0 | R33: 1 | S33: 0 | T33: 1 | U33: 1 | V33: 0 | W33: 1 | X33: 1 | Y33: 0 | Z33: 0 | AA33: 0 | AB33: 0 | AC33: 0 | AD33: 0 | AE33: 0 | AF33: 1 | AG33: =SUM(C33:AF33) -> 9 | AH33: 05:00-18:00 | AI33: 0 | AJ33: 1 hr | AK33: 500 m | AL33: 4.4 | AM33: 4.4 | AN33: 3.9 | AO33: 18.7881 | AP33: 99.0003
A34: 32 | B34: Sunday Night Market (Walking Street) | C34: 1 | D34: 0 | E34: 0 | F34: 0 | G34: 0 | H34: 0 | I34: 0 | J34: 0 | K34: 0 | L34: 1 | M34: 0 | N34: 1 | O34: 0 | P34: 1 | Q34: 0 | R34: 1 | S34: 0 | T34: 1 | U34: 0 | V34: 1 | W34: 0 | X34: 1 | Y34: 0 | Z34: 1 | AA34: 0 | AB34: 1 | AC34: 1 | AD34: 0 | AE34: 0 | AF34: 1 | AG34: =SUM(C34:AF34) -> 12 | AH34: 17:00-22:30 | AI34: 0 | AJ34: 2 hr | AK34: 1.5 km | AL34: 4.5 | AM34: 4.5 | AN34: 4.3 | AO34: 18.7875 | AP34: 98.9935
A35: 33 | B35: Saturday Night Market (Wua Lai Road) | C35: 1 | D35: 0 | E35: 0 | F35: 0 | G35: 0 | H35: 0 | I35: 0 | J35: 0 | K35: 0 | L35: 1 | M35: 0 | N35: 1 | O35: 0 | P35: 1 | Q35: 0 | R35: 1 | S35: 0 | T35: 1 | U35: 0 | V35: 1 | W35: 0 | X35: 1 | Y35: 1 | Z35: 1 | AA35: 0 | AB35: 1 | AC35: 1 | AD35: 0 | AE35: 0 | AF35: 1 | AG35: =SUM(C35:AF35) -> 13 | AH35: 18:00-23:00 | AI35: 0 | AJ35: 2 hr | AK35: 1.2 km | AL35: 4.4 | AM35: 4.5 | AN35: 4 | AO35: 18.7815 | AP35: 98.9875
A36: 34 | B36: Chiang Mai Gate Market | C36: 1 | D36: 0 | E36: 0 | F36: 0 | G36: 1 | H36: 0 | I36: 1 | J36: 1 | K36: 1 | L36: 1 | M36: 0 | N36: 1 | O36: 0 | P36: 1 | Q36: 0 | R36: 1 | S36: 0 | T36: 1 | U36: 0 | V36: 0 | W36: 0 | X36: 1 | Y36: 0 | Z36: 1 | AA36: 0 | AB36: 1 | AC36: 1 | AD36: 0 | AE36: 0 | AF36: 1 | AG36: =SUM(C36:AF36) -> 15 | AH36: 04:00-24:00 | AI36: 0 | AJ36: 1 hr | AK36: 400 m | AL36: 4.4 | AM36: 4.6 | AO36: 18.7819 | AP36: 98.9907
A37: 35 | B37: Ton Lamyai Flower Market | C37: 0 | D37: 1 | E37: 1 | F37: 1 | G37: 1 | H37: 0 | I37: 1 | J37: 1 | K37: 1 | L37: 1 | M37: 0 | N37: 1 | O37: 0 | P37: 1 | Q37: 0 | R37: 1 | S37: 0 | T37: 1 | U37: 1 | V37: 0 | W37: 0 | X37: 1 | Y37: 0 | Z37: 1 | AA37: 0 | AB37: 1 | AC37: 1 | AD37: 0 | AE37: 0 | AF37: 1 | AG37: =SUM(C37:AF37) -> 18 | AH37: 05:00-17:00 | AI37: 0 | AJ37: 1 hr | AK37: 400 m | AL37: 4.3 | AN37: 3.5 | AO37: 18.7879 | AP37: 99.0008
A38: 36 | B38: Baan Tawai Handicraft Village | C38: 0 | D38: 1 | E38: 1 | F38: 0 | G38: 1 | H38: 1 | I38: 1 | J38: 1 | K38: 1 | L38: 1 | M38: 0 | N38: 1 | O38: 1 | P38: 0 | Q38: 0 | R38: 1 | S38: 1 | T38: 1 | U38: 1 | V38: 0 | W38: 1 | X38: 1 | Y38: 1 | Z38: 1 | AA38: 1 | AB38: 1 | AC38: 1 | AD38: 0 | AE38: 0 | AF38: 1 | AG38: =SUM(C38:AF38) -> 22 | AH38: 09:00-17:00 | AI38: 0 | AJ38: 1.5 hr | AK38: 700 m | AL38: 4.6 | AM38: 4.6 | AN38: 3.4 | AO38: 18.6985 | AP38: 98.893
A39: 37 | B39: Bo Sang Umbrella Village | C39: 0 | D39: 1 | E39: 1 | F39: 0 | G39: 1 | H39: 1 | I39: 1 | J39: 1 | K39: 1 | L39: 1 | M39: 1 | N39: 1 | O39: 1 | P39: 0 | Q39: 0 | R39: 1 | S39: 1 | T39: 1 | U39: 1 | V39: 1 | W39: 0 | X39: 1 | Y39: 1 | Z39: 1 | AA39: 1 | AB39: 1 | AC39: 1 | AD39: 0 | AE39: 0 | AF39: 1 | AG39: =SUM(C39:AF39) -> 23 | AH39: 08:00-17:00 | AI39: 0 | AJ39: 1 hr | AK39: 500 m | AL39: 4.2 | AM39: 4.1 | AN39: 4.2 | AO39: 18.761 | AP39: 99.116
A40: 38 | B40: San Kamphaeng Silk Village | C40: 0 | D40: 1 | E40: 1 | F40: 0 | G40: 1 | H40: 1 | I40: 1 | J40: 1 | K40: 1 | L40: 1 | M40: 1 | N40: 1 | O40: 1 | P40: 0 | Q40: 0 | R40: 1 | S40: 1 | T40: 1 | U40: 1 | V40: 1 | W40: 0 | X40: 1 | Y40: 1 | Z40: 1 | AA40: 1 | AB40: 1 | AC40: 1 | AD40: 0 | AE40: 0 | AF40: 1 | AG40: =SUM(C40:AF40) -> 23 | AH40: 8:30-17:30 | AI40: 0 | AJ40: 1.5 hr | AK40: 800 m | AL40: 4 | AO40: 18.729 | AP40: 99.147
...

Sheet Questionaire
A1: Criteria | B1: Sub-criteria | C1: Does It Currently Exist? (Yes/No) | D1: Weight
A2: Safety | B2: Traffic Safety
B3: Crime Prevention (Presence of police, CCTV)
B4: Tourist Scam Prevention (scams, pickpocketing, overcharging, or misleading information)
B5: Emergency Accessibility (Access to hospitals within 8–10 minutes <WHO Health Systems Guidelines>)
B6: Environmental Safety (Low exposure to air pollution, flooding, or extreme weather conditions)
A7: Comfort Level | B7: Availability of Seating
B8: Shade and Weather Shelter (Access to shaded walkways, trees, or rain shelters in hot or wet weather)
B9: Low-noise environments with limited overcrowding
B10: Cleanliness and Maintenance
B11: Visual Comfort (Clear signage, readable fonts, multilingual information, and calming visual design)
A12: Accessibility | B12: Barrier-Free Pathways (Availability of smooth, wide walkways with ramps, tactile paving, and curb cuts)
B13: Step-Free Access to Sites (ramps/elevators)
B14: Toilet Accessibility (Availability of clean, accessible toilets that are elderly-friendly)
B15: Accessible Public Transport (buses or shuttles with low floors, handrails, and priority seating)
B16: Support for Wheelchair Users (wheelchair rentals, staff assistance)
A17: Pathway | B17: Distance Between Stops (Distances between activity locations should be manageable for limited mobility)
B18: Availability of Rest Areas (Presence of shaded benches or resting spots every 250–400 meters)
B19: Route Slope & Gradient (Inclines along walking paths should be gentle, ideally <5% gradient)
B20: Shaded Walking Paths (Protection from heat or sun exposure with trees, roofs, or covered walkways)
B21: Surface Condition (Presence of non-slip flooring materials and level walkways)
A22: Heritage & Cultural Value | B22: Heritage Designation (officially recognized by e.g., UNESCO, national or local heritage site)
B23: Community and Cultural Engagement (local markets, artisans, traditional music, crafts, rituals, or storytelling)
B24: Hands-on Workshops (e.g., crafts)
B25: Elderly-friendly Activities
B26: Educational Value (interpretation signage, guided tours, or audio guides)
A27: Scenery & Aesthetic | B27: Photo Spots Availability (Presence of designated scenic spots)
B28: Visual Aesthetic Quality (Green spaces, gardens, historic architecture, natural views)
B29: Landscape Diversity (mountain, river, rice fields, old city)
B30: Sunrise/Sunset Viewing Spots
B31: Cultural Aesthetic Elements (Traditional art, temples, local decor enhancing cultural feel)

Sheet Data_Adj
A1: No. | B1: Name | C1: Safety | I1: Comfort Level | O1: Accessibility | U1: Walking Distance | AA1: Heritage & Cultural Value | AG1: Scenery & Aesthetic | AM1: Total | AN1: Time window | AO1: Entrance fee | AP1: Stay | AQ1: Real | AR1: duration | AS1: Walking | AT1: Real | AU1: distance | AV1: Google Satisfaction score | AW1: Trip.com Satisfaction score | AX1: Wongnai Satisfaction score | AY1: Latitude | AZ1: Longitude
A2: No | C2: S1 | D2: S2 | E2: S3 | F2: S4 | G2: S5 | I2: C1 | J2: C2 | K2: C3 | L2: C4 | M2: C5 | O2: A1 | P2: A2 | Q2: A3 | R2: A4 | S2: A5 | U2: W1 | V2: W2 | W2: W3 | X2: W4 | Y2: W5 | AA2: H1 | AB2: H2 | AC2: H3 | AD2: H4 | AE2: H5 | AG2: SC1 | AH2: SC2 | AI2: SC3 | AJ2: SC4 | AK2: SC5 | AQ2: Use | AT2: Use
A3: 1 | B3: Wat Phra That Doi Suthep | C3: 0 | D3: 1 | E3: 1 | F3: 0 | G3: 1 | H3: =SUM(C3:G3) -> 3 | I3: 1 | J3: 1 | K3: 1 | L3: 1 | M3: 1 | N3: =SUM(I3:M3) -> 5 | O3: 0 | P3: 1 | Q3: 1 | R3: 0 | S3: 0 | T3: =SUM(O3:S3) -> 2 | U3: 0 | V3: 1 | W3: 0 | X3: 1 | Y3: 1 | Z3: =SUM(U3:Y3) -> 3 | AA3: 1 | AB3: 1 | AC3: 0 | AD3: 0 | AE3: 1 | AF3: =SUM(AA3:AE3) -> 3 | AG3: 1 | AH3: 1 | AI3: 1 | AJ3: 1 | AK3: 1 | AL3: =SUM(AG3:AK3) -> 5 | AM3: =SUM(C3:AK3) -> 37 | AN3: 06:00-20:00 | AO3: 20 | AP3: 1.5 | AQ3: =IF(AR3="hr",AP3,AP3/60) -> 1.5 | AR3: hr | AS3: 500 | AT3: =IF(AU3="m",AS3*1,AS3*1000) -> 500 | AU3: m | AV3: 4.7 | AW3: 4.7 | AX3: 4.5 | AY3: 18.805 | AZ3: 98.9216
A4: 2 | B4: Wat Chedi Luang | C4: 1 | D4: 1 | E4: 1 | F4: 1 | G4: 1 | H4: =SUM(C4:G4) -> 5 | I4: 1 | J4: 1 | K4: 1 | L4: 1 | M4: 1 | N4: =SUM(I4:M4) -> 5 | O4: 1 | P4: 1 | Q4: 1 | R4: 1 | S4: 1 | T4: =SUM(O4:S4) -> 5 | U4: 1 | V4: 1 | W4: 1 | X4: 1 | Y4: 1 | Z4: =SUM(U4:Y4) -> 5 | AA4: 1 | AB4: 1 | AC4: 0 | AD4: 1 | AE4: 1 | AF4: =SUM(AA4:AE4) -> 4 | AG4: 1 | AH4: 1 | AI4: 0 | AJ4: 0 | AK4: 1 | AL4: =SUM(AG4:AK4) -> 3 | AM4: =SUM(C4:AK4) -> 51 | AN4: 05:00-22:00 | AO4: 0 | AP4: 1 | AQ4: =IF(AR4="hr",AP4,AP4/60) -> 1 | AR4: hr | AS4: 300 | AT4: =IF(AU4="m",AS4*1,AS4*1000) -> 300 | AU4: m | AV4: 4.7 | AW4: 4.8 | AX4: 4.5 | AY4: 18.787 | AZ4: 98.9866
A5: 3 | B5: Wat Phra Singh | C5: 1 | D5: 1 | E5: 1 | F5: 1 | G5: 1 | H5: =SUM(C5:G5) -> 5 | I5: 1 | J5: 1 | K5: 1 | L5: 1 | M5: 1 | N5: =SUM(I5:M5) -> 5 | O5: 1 | P5: 1 | Q5: 1 | R5: 1 | S5: 1 | T5: =SUM(O5:S5) -> 5 | U5: 1 | V5: 1 | W5: 1 | X5: 1 | Y5: 1 | Z5: =SUM(U5:Y5) -> 5 | AA5: 1 | AB5: 1 | AC5: 0 | AD5: 1 | AE5: 1 | AF5: =SUM(AA5:AE5) -> 4 | AG5: 1 | AH5: 1 | AI5: 0 | AJ5: 0 | AK5: 1 | AL5: =SUM(AG5:AK5) -> 3 | AM5: =SUM(C5:AK5) -> 51 | AN5: 05:30-19:30 | AO5: 0 | AP5: 1 | AQ5: =IF(AR5="hr",AP5,AP5/60) -> 1 | AR5: hr | AS5: 250 | AT5: =IF(AU5="m",AS5*1,AS5*1000) -> 250 | AU5: m | AV5: 4.7 | AW5: 4.7 | AX5: 4.6 | AY5: 18.7885 | AZ5: 98.982
A6: 4 | B6: Wat Umong | C6: 1 | D6: 1 | E6: 1 | F6: 0 | G6: 1 | H6: =SUM(C6:G6) -> 4 | I6: 1 | J6: 1 | K6: 1 | L6: 1 | M6: 1 | N6: =SUM(I6:M6) -> 5 | O6: 0 | P6: 0 | Q6: 1 | R6: 0 | S6: 0 | T6: =SUM(O6:S6) -> 1 | U6: 1 | V6: 1 | W6: 0 | X6: 1 | Y6: 0 | Z6: =SUM(U6:Y6) -> 3 | AA6: 1 | AB6: 1 | AC6: 0 | AD6: 1 | AE6: 1 | AF6: =SUM(AA6:AE6) -> 4 | AG6: 1 | AH6: 1 | AI6: 1 | AJ6: 0 | AK6: 1 | AL6: =SUM(AG6:AK6) -> 4 | AM6: =SUM(C6:AK6) -> 38 | AN6: 05:00-20:00 | AO6: 0 | AP6: 1 | AQ6: =IF(AR6="hr",AP6,AP6/60) -> 1 | AR6: hr | AS6: 400 | AT6: =IF(AU6="m",AS6*1,AS6*1000) -> 400 | AU6: m | AV6: 4.6 | AW6: 4.7 | AX6: 4.3 | AY6: 18.7827 | AZ6: 98.9521
A7: 5 | B7: Wat Chiang Man | C7: 1 | D7: 1 | E7: 1 | F7: 1 | G7: 1 | H7: =SUM(C7:G7) -> 5 | I7: 1 | J7: 1 | K7: 1 | L7: 1 | M7: 1 | N7: =SUM(I7:M7) -> 5 | O7: 1 | P7: 1 | Q7: 1 | R7: 1 | S7: 1 | T7: =SUM(O7:S7) -> 5 | U7: 1 | V7: 1 | W7: 1 | X7: 1 | Y7: 1 | Z7: =SUM(U7:Y7) -> 5 | AA7: 1 | AB7: 1 | AC7: 0 | AD7: 1 | AE7: 1 | AF7: =SUM(AA7:AE7) -> 4 | AG7: 1 | AH7: 1 | AI7: 0 | AJ7: 0 | AK7: 1 | AL7: =SUM(AG7:AK7) -> 3 | AM7: =SUM(C7:AK7) -> 51 | AN7: 06:00-18:00 | AO7: 0 | AP7: 1 | AQ7: =IF(AR7="hr",AP7,AP7/60) -> 1 | AR7: hr | AS7: 300 | AT7: =IF(AU7="m",AS7*1,AS7*1000) -> 300 | AU7: m | AV7: 4.6 | AW7: 4.6 | AX7: 4.1 | AY7: 18.7938 | AZ7: 98.9893
A8: 6 | B8: Wat Suan Dok | C8: 1 | D8: 1 | E8: 1 | F8: 1 | G8: 1 | H8: =SUM(C8:G8) -> 5 | I8: 1 | J8: 1 | K8: 1 | L8: 1 | M8: 1 | N8: =SUM(I8:M8) -> 5 | O8: 1 | P8: 1 | Q8: 1 | R8: 1 | S8: 1 | T8: =SUM(O8:S8) -> 5 | U8: 1 | V8: 1 | W8: 1 | X8: 1 | Y8: 1 | Z8: =SUM(U8:Y8) -> 5 | AA8: 1 | AB8: 1 | AC8: 1 | AD8: 1 | AE8: 1 | AF8: =SUM(AA8:AE8) -> 5 | AG8: 1 | AH8: 1 | AI8: 0 | AJ8: 1 | AK8: 1 | AL8: =SUM(AG8:AK8) -> 4 | AM8: =SUM(C8:AK8) -> 54 | AN8: 06:00-18:00 | AO8: 0 | AP8: 1 | AQ8: =IF(AR8="hr",AP8,AP8/60) -> 1 | AR8: hr | AS8: 350 | AT8: =IF(AU8="m",AS8*1,AS8*1000) -> 350 | AU8: m | AV8: 4.6 | AW8: 4.6 | AX8: 4.3 | AY8: 18.7882 | AZ8: 98.9678
A9: 7 | B9: Wat Lok Moli | C9: 1 | D9: 1 | E9: 1 | F9: 0 | G9: 1 | H9: =SUM(C9:G9) -> 4 | I9: 1 | J9: 1 | K9: 1 | L9: 1 | M9: 1 | N9: =SUM(I9:M9) -> 5 | O9: 0 | P9: 1 | Q9: 0 | R9: 1 | S9: 0 | T9: =SUM(O9:S9) -> 2 | U9: 1 | V9: 1 | W9: 1 | X9: 1 | Y9: 0 | Z9: =SUM(U9:Y9) -> 4 | AA9: 1 | AB9: 1 | AC9: 0 | AD9: 1 | AE9: 1 | AF9: =SUM(AA9:AE9) -> 4 | AG9: 1 | AH9: 1 | AI9: 0 | AJ9: 0 | AK9: 1 | AL9: =SUM(AG9:AK9) -> 3 | AM9: =SUM(C9:AK9) -> 41 | AN9: 08:00-17:30 | AO9: 0 | AP9: 45 | AQ9: =IF(AR9="hr",AP9,AP9/60) -> 0.75 | AR9: min | AS9: 300 | AT9: =IF(AU9="m",AS9*1,AS9*1000) -> 300 | AU9: m | AV9: 4.7 | AW9: 4.8 | AX9: 4.4 | AY9: 18.786 | AZ9: 98.9826
A10: 8 | B10: Wat Sri Suphan (Silver Temple) | C10: 1 | D10: 1 | E10: 1 | F10: 0 | G10: 1 | H10: =SUM(C10:G10) -> 4 | I10: 0 | J10: 1 | K10: 1 | L10: 1 | M10: 1 | N10: =SUM(I10:M10) -> 4 | O10: 0 | P10: 0 | Q10: 0 | R10: 0 | S10: 0 | T10: =SUM(O10:S10) -> 0 | U10: 1 | V10: 0 | W10: 1 | X10: 0 | Y10: 0 | Z10: =SUM(U10:Y10) -> 2 | AA10: 1 | AB10: 1 | AC10: 1 | AD10: 1 | AE10: 1 | AF10: =SUM(AA10:AE10) -> 5 | AG10: 1 | AH10: 1 | AI10: 0 | AJ10: 0 | AK10: 1 | AL10: =SUM(AG10:AK10) -> 3 | AM10: =SUM(C10:AK10) -> 33 | AN10: 06:00-18:00 | AO10: 0 | AP10: 1 | AQ10: =IF(AR10="hr",AP10,AP10/60) -> 1 | AR10: hr | AS10: 300 | AT10: =IF(AU10="m",AS10*1,AS10*1000) -> 300 | AU10: m | AV10: 4.5 | AW10: 5 | AX10: 4.3 | AY10: 18.7787 | AZ10: 98.9837
A11: 9 | B11: Wat Buppharam | C11: 0 | D11: 1 | E11: 1 | F11: 1 | G11: 1 | H11: =SUM(C11:G11) -> 4 | I11: 1 | J11: 1 | K11: 1 | L11: 1 | M11: 1 | N11: =SUM(I11:M11) -> 5 | O11: 0 | P11: 0 | Q11: 0 | R11: 1 | S11: 0 | T11: =SUM(O11:S11) -> 1 | U11: 1 | V11: 1 | W11: 1 | X11: 1 | Y11: 0 | Z11: =SUM(U11:Y11) -> 4 | AA11: 1 | AB11: 1 | AC11: 0 | AD11: 1 | AE11: 1 | AF11: =SUM(AA11:AE11) -> 4 | AG11: 1 | AH11: 1 | AI11: 0 | AJ11: 0 | AK11: 1 | AL11: =SUM(AG11:AK11) -> 3 | AM11: =SUM(C11:AK11) -> 39 | AN11: 08:00-18:00 | AO11: 0 | AP11: 45 | AQ11: =IF(AR11="hr",AP11,AP11/60) -> 0.75 | AR11: min | AS11: 250 | AT11: =IF(AU11="m",AS11*1,AS11*1000) -> 250 | AU11: m | AV11: 4.5 | AW11: 4.5 | AX11: 3.8 | AY11: 18.788 | AZ11: 98.9983
A12: 10 | B12: Wat Ket Karam | C12: 1 | D12: 1 | E12: 1 | F12: 1 | G12: 1 | H12: =SUM(C12:G12) -> 5 | I12: 1 | J12: 1 | K12: 1 | L12: 1 | M12: 1 | N12: =SUM(I12:M12) -> 5 | O12: 0 | P12: 1 | Q12: 1 | R12: 0 | S12: 0 | T12: =SUM(O12:S12) -> 2 | U12: 1 | V12: 1 | W12: 1 | X12: 1 | Y12: 1 | Z12: =SUM(U12:Y12) -> 5 | AA12: 1 | AB12: 1 | AC12: 0 | AD12: 0 | AE12: 0 | AF12: =SUM(AA12:AE12) -> 2 | AG12: 1 | AH12: 1 | AI12: 0 | AJ12: 0 | AK12: 1 | AL12: =SUM(AG12:AK12) -> 3 | AM12: =SUM(C12:AK12) -> 41 | AN12: 06:00-18:00 | AO12: 0 | AP12: 45 | AQ12: =IF(AR12="hr",AP12,AP12/60) -> 0.75 | AR12: min | AS12: 250 | AT12: =IF(AU12="m",AS12*1,AS12*1000) -> 250 | AU12: m | AV12: 4.6 | AW12: 4.9 | AX12: 4.2 | AY12: 18.7924 | AZ12: 99.0034
A13: 11 | B13: Chiang Mai City Arts & Cultural Centre | C13: 1 | D13: 1 | E13: 1 | F13: 1 | G13: 1 | H13: =SUM(C13:G13) -> 5 | I13: 1 | J13: 1 | K13: 1 | L13: 1 | M13: 1 | N13: =SUM(I13:M13) -> 5 | O13: 1 | P13: 1 | Q13: 1 | R13: 1 | S13: 1 | T13: =SUM(O13:S13) -> 5 | U13: 1 | V13: 1 | W13: 1 | X13: 1 | Y13: 1 | Z13: =SUM(U13:Y13) -> 5 | AA13: 1 | AB13: 1 | AC13: 0 | AD13: 1 | AE13: 1 | AF13: =SUM(AA13:AE13) -> 4 | AG13: 1 | AH13: 1 | AI13: 0 | AJ13: 0 | AK13: 1 | AL13: =SUM(AG13:AK13) -> 3 | AM13: =SUM(C13:AK13) -> 51 | AN13: 08:30-16:30 | AO13: 90 | AP13: 1.5 | AQ13: =IF(AR13="hr",AP13,AP13/60) -> 1.5 | AR13: hr | AS13: 300 | AT13: =IF(AU13="m",AS13*1,AS13*1000) -> 300 | AU13: m | AV13: 4.5 | AW13: 4.2 | AX13: 4.1 | AY13: 18.7889 | AZ13: 98.9908
A14: 12 | B14: Lanna Folklife Museum | C14: 1 | D14: 1 | E14: 1 | F14: 1 | G14: 1 | H14: =SUM(C14:G14) -> 5 | I14: 1 | J14: 1 | K14: 1 | L14: 1 | M14: 1 | N14: =SUM(I14:M14) -> 5 | O14: 1 | P14: 1 | Q14: 1 | R14: 1 | S14: 1 | T14: =SUM(O14:S14) -> 5 | U14: 1 | V14: 1 | W14: 1 | X14: 1 | Y14: 1 | Z14: =SUM(U14:Y14) -> 5 | AA14: 1 | AB14: 1 | AC14: 0 | AD14: 1 | AE14: 1 | AF14: =SUM(AA14:AE14) -> 4 | AG14: 1 | AH14: 1 | AI14: 0 | AJ14: 0 | AK14: 1 | AL14: =SUM(AG14:AK14) -> 3 | AM14: =SUM(C14:AK14) -> 51 | AN14: 08:30-16:30 | AO14: 20 | AP14: 1.5 | AQ14: =IF(AR14="hr",AP14,AP14/60) -> 1.5 | AR14: hr | AS14: 300 | AT14: =IF(AU14="m",AS14*1,AS14*1000) -> 300 | AU14: m | AV14: 4.3 | AW14: 4.3 | AX14: 4.6 | AY14: 18.7902 | AZ14: 98.9884
A15: 13 | B15: Chiang Mai National Museum | C15: 1 | D15: 1 | E15: 1 | F15: 1 | G15: 1 | H15: =SUM(C15:G15) -> 5 | I15: 1 | J15: 1 | K15: 1 | L15: 1 | M15: 1 | N15: =SUM(I15:M15) -> 5 | O15: 1 | P15: 1 | Q15: 1 | R15: 0 | S15: 1 | T15: =SUM(O15:S15) -> 4 | U15: 1 | V15: 1 | W15: 1 | X15: 1 | Y15: 1 | Z15: =SUM(U15:Y15) -> 5 | AA15: 1 | AB15: 1 | AC15: 0 | AD15: 1 | AE15: 1 | AF15: =SUM(AA15:AE15) -> 4 | AG15: 1 | AH15: 1 | AI15: 0 | AJ15: 0 | AK15: 1 | AL15: =SUM(AG15:AK15) -> 3 | AM15: =SUM(C15:AK15) -> 49 | AN15: 09:00-16:00 | AO15: 20 | AP15: 1 | AQ15: =IF(AR15="hr",AP15,AP15/60) -> 1 | AR15: hr | AS15: 200 | AT15: =IF(AU15="m",AS15*1,AS15*1000) -> 200 | AU15: m | AV15: 4.2 | AW15: 4.4 | AX15: 3.6 | AY15: 18.8112 | AZ15: 98.9764
A16: 14 | B16: Highland People Discovery Museum | C16: 1 | D16: 1 | E16: 1 | F16: 0 | G16: 1 | H16: =SUM(C16:G16) -> 4 | I16: 1 | J16: 1 | K16: 1 | L16: 1 | M16: 1 | N16: =SUM(I16:M16) -> 5 | O16: 1 | P16: 0 | Q16: 1 | R16: 0 | S16: 0 | T16: =SUM(O16:S16) -> 2 | U16: 1 | V16: 1 | W16: 1 | X16: 1 | Y16: 1 | Z16: =SUM(U16:Y16) -> 5 | AA16: 1 | AB16: 1 | AC16: 0 | AD16: 1 | AE16: 1 | AF16: =SUM(AA16:AE16) -> 4 | AG16: 1 | AH16: 1 | AI16: 1 | AJ16: 0 | AK16: 1 | AL16: =SUM(AG16:AK16) -> 4 | AM16: =SUM(C16:AK16) -> 44 | AN16: 08:30-16:00 | AO16: 0 | AP16: 1 | AQ16: =IF(AR16="hr",AP16,AP16/60) -> 1 | AR16: hr | AS16: 200 | AT16: =IF(AU16="m",AS16*1,AS16*1000) -> 200 | AU16: m | AV16: 4.3 | AW16: 4.6 | AY16: 18.8214 | AZ16: 98.9747
A17: 15 | B17: MAIIAM Contemporary Art Museum | C17: 1 | D17: 1 | E17: 1 | F17: 0 | G17: 1 | H17: =SUM(C17:G17) -> 4 | I17: 1 | J17: 1 | K17: 1 | L17: 1 | M17: 1 | N17: =SUM(I17:M17) -> 5 | O17: 1 | P17: 1 | Q17: 1 | R17: 0 | S17: 1 | T17: =SUM(O17:S17) -> 4 | U17: 1 | V17: 0 | W17: 1 | X17: 1 | Y17: 1 | Z17: =SUM(U17:Y17) -> 4 | AA17: 0 | AB17: 0 | AC17: 0 | AD17: 1 | AE17: 1 | AF17: =SUM(AA17:AE17) -> 2 | AG17: 1 | AH17: 1 | AI17: 0 | AJ17: 0 | AK17: 0 | AL17: =SUM(AG17:AK17) -> 2 | AM17: =SUM(C17:AK17) -> 40 | AN17: 10:00-18:00 | AO17: 150 | AP17: 1.5 | AQ17: =IF(AR17="hr",AP17,AP17/60) -> 1.5 | AR17: hr | AS17: 300 | AT17: =IF(AU17="m",AS17*1,AS17*1000) -> 300 | AU17: m | AV17: 4.4 | AW17: 4.8 | AX17: 4 | AY17: 18.7572 | AZ17: 99.0937
A18: 16 | B18: Art in Paradise 3D Museum | C18: 1 | D18: 1 | E18: 1 | F18: 1 | G18: 1 | H18: =SUM(C18:G18) -> 5 | I18: 0 | J18: 1 | K18: 1 | L18: 1 | M18: 1 | N18: =SUM(I18:M18) -> 4 | O18: 1 | P18: 1 | Q18: 1 | R18: 1 | S18: 1 | T18: =SUM(O18:S18) -> 5 | U18: 1 | V18: 0 | W18: 1 | X18: 1 | Y18: 1 | Z18: =SUM(U18:Y18) -> 4 | AA18: 0 | AB18: 0 | AC18: 0 | AD18: 0 | AE18: 0 | AF18: =SUM(AA18:AE18) -> 0 | AG18: 1 | AH18: 0 | AI18: 0 | AJ18: 0 | AK18: 0 | AL18: =SUM(AG18:AK18) -> 1 | AM18: =SUM(C18:AK18) -> 37 | AN18: 09:00-21:00 | AO18: 200 | AP18: 2 | AQ18: =IF(AR18="hr",AP18,AP18/60) -> 2 | AR18: hr | AS18: 500 | AT18: =IF(AU18="m",AS18*1,AS18*1000) -> 500 | AU18: m | AV18: 4.5 | AW18: 4.7 | AX18: 4 | AY18: 18.7828 | AZ18: 99.0003
A19: 17 | B19: Chiang Mai Historical Centre | C19: 1 | D19: 1 | E19: 1 | F19: 1 | G19: 1 | H19: =SUM(C19:G19) -> 5 | I19: 1 | J19: 1 | K19: 1 | L19: 1 | M19: 1 | N19: =SUM(I19:M19) -> 5 | O19: 1 | P19: 1 | Q19: 1 | R19: 1 | S19: 1 | T19: =SUM(O19:S19) -> 5 | U19: 1 | V19: 1 | W19: 1 | X19: 1 | Y19: 1 | Z19: =SUM(U19:Y19) -> 5 | AA19: 1 | AB19: 1 | AC19: 0 | AD19: 1 | AE19: 1 | AF19: =SUM(AA19:AE19) -> 4 | AG19: 1 | AH19: 1 | AI19: 0 | AJ19: 0 | AK19: 1 | AL19: =SUM(AG19:AK19) -> 3 | AM19: =SUM(C19:AK19) -> 51 | AN19: 08:30-17:00 | AO19: 20 | AP19: 1 | AQ19: =IF(AR19="hr",AP19,AP19/60) -> 1 | AR19: hr | AS19: 200 | AT19: =IF(AU19="m",AS19*1,AS19*1000) -> 200 | AU19: m | AV19: 4.2 | AW19: 5 | AX19: 4.4 | AY19: 18.7902 | AZ19: 98.9863
A20: 18 | B20: Museum of World Insects and Natural Wonders | C20: 0 | D20: 1 | E20: 1 | F20: 0 | G20: 1 | H20: =SUM(C20:G20) -> 3 | I20: 0 | J20: 1 | K20: 1 | L20: 0 | M20: 0 | N20: =SUM(I20:M20) -> 2 | O20: 0 | P20: 0 | Q20: 0 | R20: 0 | S20: 0 | T20: =SUM(O20:S20) -> 0 | U20: 1 | V20: 0 | W20: 1 | X20: 1 | Y20: 1 | Z20: =SUM(U20:Y20) -> 4 | AA20: 0 | AB20: 0 | AC20: 0 | AD20: 0 | AE20: 1 | AF20: =SUM(AA20:AE20) -> 1 | AG20: 0 | AH20: 0 | AI20: 0 | AJ20: 0 | AK20: 0 | AL20: =SUM(AG20:AK20) -> 0 | AM20: =SUM(C20:AK20) -> 20 | AN20: 10:00-15:00 | AO20: 200 | AP20: 1 | AQ20: =IF(AR20="hr",AP20,AP20/60) -> 1 | AR20: hr | AS20: 150 | AT20: =IF(AU20="m",AS20*1,AS20*1000) -> 150 | AU20: m | AV20: 4.3 | AW20: 4.3 | AY20: 18.7961 | AZ20: 98.9706
A21: 19 | B21: Dara Pirom Palace Museum | C21: 1 | D21: 1 | E21: 1 | F21: 0 | G21: 1 | H21: =SUM(C21:G21) -> 4 | I21: 1 | J21: 1 | K21: 1 | L21: 1 | M21: 1 | N21: =SUM(I21:M21) -> 5 | O21: 0 | P21: 0 | Q21: 0 | R21: 0 | S21: 0 | T21: =SUM(O21:S21) -> 0 | U21: 1 | V21: 1 | W21: 1 | X21: 1 | Y21: 1 | Z21: =SUM(U21:Y21) -> 5 | AA21: 1 | AB21: 1 | AC21: 0 | AD21: 1 | AE21: 1 | AF21: =SUM(AA21:AE21) -> 4 | AG21: 1 | AH21: 1 | AI21: 1 | AJ21: 0 | AK21: 1 | AL21: =SUM(AG21:AK21) -> 4 | AM21: =SUM(C21:AK21) -> 40 | AN21: 09:00-17:00 | AO21: 20 | AP21: 1 | AQ21: =IF(AR21="hr",AP21,AP21/60) -> 1 | AR21: hr | AS21: 200 | AT21: =IF(AU21="m",AS21*1,AS21*1000) -> 200 | AU21: m | AV21: 4.7 | AW21: 5 | AX21: 4.2 | AY21: 18.931 | AZ21: 98.892
A22: 20 | B22: Tribal Museum (Highland People Discovery) | C22: 1 | D22: 1 | E22: 1 | F22: 0 | G22: 1 | H22: =SUM(C22:G22) -> 4 | I22: 1 | J22: 1 | K22: 1 | L22: 1 | M22: 1 | N22: =SUM(I22:M22) -> 5 | O22: 1 | P22: 0 | Q22: 1 | R22: 0 | S22: 0 | T22: =SUM(O22:S22) -> 2 | U22: 1 | V22: 1 | W22: 1 | X22: 1 | Y22: 1 | Z22: =SUM(U22:Y22) -> 5 | AA22: 1 | AB22: 1 | AC22: 0 | AD22: 1 | AE22: 1 | AF22: =SUM(AA22:AE22) -> 4 | AG22: 1 | AH22: 1 | AI22: 1 | AJ22: 0 | AK22: 1 | AL22: =SUM(AG22:AK22) -> 4 | AM22: =SUM(C22:AK22) -> 44 | AN22: 09:00-16:00 | AO22: 0 | AP22: 1 | AQ22: =IF(AR22="hr",AP22,AP22/60) -> 1 | AR22: hr | AS22: 200 | AT22: =IF(AU22="m",AS22*1,AS22*1000) -> 200 | AU22: m | AV22: 3.6 | AY22: 18.8214 | AZ22: 98.9747
A23: 21 | B23: Elephant Nature Park | C23: 1 | D23: 1 | E23: 1 | F23: 0 | G23: 0 | H23: =SUM(C23:G23) -> 3 | I23: 1 | J23: 1 | K23: 1 | L23: 1 | M23: 1 | N23: =SUM(I23:M23) -> 5 | O23: 0 | P23: 0 | Q23: 1 | R23: 0 | S23: 0 | T23: =SUM(O23:S23) -> 1 | U23: 0 | V23: 1 | W23: 0 | X23: 1 | Y23: 0 | Z23: =SUM(U23:Y23) -> 2 | AA23: 0 | AB23: 1 | AC23: 0 | AD23: 1 | AE23: 1 | AF23: =SUM(AA23:AE23) -> 3 | AG23: 1 | AH23: 1 | AI23: 1 | AJ23: 0 | AK23: 1 | AL23: =SUM(AG23:AK23) -> 4 | AM23: =SUM(C23:AK23) -> 32 | AN23: 08:00-17:00 | AO23: 0 | AP23: 5 | AQ23: =IF(AR23="hr",AP23,AP23/60) -> 5 | AR23: hr | AS23: 2 | AT23: =IF(AU23="m",AS23*1,AS23*1000) -> 2000 | AU23: km | AV23: 4.8 | AW23: 4.5 | AY23: 18.8853 | AZ23: 99.0008
A24: 22 | B24: Chiang Mai Zoo | C24: 1 | D24: 1 | E24: 1 | F24: 0 | G24: 1 | H24: =SUM(C24:G24) -> 4 | I24: 1 | J24: 1 | K24: 0 | L24: 1 | M24: 1 | N24: =SUM(I24:M24) -> 4 | O24: 0 | P24: 1 | Q24: 1 | R24: 1 | S24: 1 | T24: =SUM(O24:S24) -> 4 | U24: 0 | V24: 1 | W24: 0 | X24: 1 | Y24: 1 | Z24: =SUM(U24:Y24) -> 3 | AA24: 0 | AB24: 0 | AC24: 0 | AD24: 1 | AE24: 1 | AF24: =SUM(AA24:AE24) -> 2 | AG24: 1 | AH24: 1 | AI24: 1 | AJ24: 0 | AK24: 0 | AL24: =SUM(AG24:AK24) -> 3 | AM24: =SUM(C24:AK24) -> 37 | AN24: 08:00-17:00 | AO24: 0 | AP24: 3 | AQ24: =IF(AR24="hr",AP24,AP24/60) -> 3 | AR24: hr | AS24: 1.5 | AT24: =IF(AU24="m",AS24*1,AS24*1000) -> 1500 | AU24: km | AV24: 3.9 | AW24: 4.5 | AX24: 4.1 | AY24: 18.8106 | AZ24: 98.9479
A25: 23 | B25: Chiang Mai Night Safari | C25: 1 | D25: 1 | E25: 1 | F25: 1 | G25: 1 | H25: =SUM(C25:G25) -> 5 | I25: 1 | J25: 1 | K25: 0 | L25: 1 | M25: 1 | N25: =SUM(I25:M25) -> 4 | O25: 1 | P25: 1 | Q25: 1 | R25: 0 | S25: 1 | T25: =SUM(O25:S25) -> 4 | U25: 1 | V25: 1 | W25: 1 | X25: 0 | Y25: 1 | Z25: =SUM(U25:Y25) -> 4 | AA25: 0 | AB25: 0 | AC25: 0 | AD25: 1 | AE25: 0 | AF25: =SUM(AA25:AE25) -> 1 | AG25: 1 | AH25: 1 | AI25: 0 | AJ25: 0 | AK25: 0 | AL25: =SUM(AG25:AK25) -> 2 | AM25: =SUM(C25:AK25) -> 38 | AN25: 11:00-22:00 | AO25: 150 | AP25: 2.5 | AQ25: =IF(AR25="hr",AP25,AP25/60) -> 2.5 | AR25: hr | AS25: 1.2 | AT25: =IF(AU25="m",AS25*1,AS25*1000) -> 1200 | AU25: km | AV25: 4.3 | AW25: 4.6 | AX25: 4.2 | AY25: 18.7422 | AZ25: 98.9172
A26: 24 | B26: Tiger Kingdom Chiang Mai | C26: 1 | D26: 1 | E26: 1 | F26: 0 | G26: 1 | H26: =SUM(C26:G26) -> 4 | I26: 1 | J26: 1 | K26: 0 | L26: 1 | M26: 1 | N26: =SUM(I26:M26) -> 4 | O26: 1 | P26: 1 | Q26: 1 | R26: 0 | S26: 0 | T26: =SUM(O26:S26) -> 3 | U26: 1 | V26: 1 | W26: 1 | X26: 1 | Y26: 1 | Z26: =SUM(U26:Y26) -> 5 | AA26: 0 | AB26: 1 | AC26: 0 | AD26: 0 | AE26: 0 | AF26: =SUM(AA26:AE26) -> 1 | AG26: 1 | AH26: 1 | AI26: 1 | AJ26: 0 | AK26: 0 | AL26: =SUM(AG26:AK26) -> 3 | AM26: =SUM(C26:AK26) -> 37 | AN26: 09:00-17:00 | AO26: 320 | AP26: 1.5 | AQ26: =IF(AR26="hr",AP26,AP26/60) -> 1.5 | AR26: hr | AS26: 0.5 | AT26: =IF(AU26="m",AS26*1,AS26*1000) -> 500 | AU26: km | AV26: 4 | AW26: 4.5 | AY26: 18.9246 | AZ26: 98.932
A27: 25 | B27: Baan Chang Elephant Park | C27: 0 | D27: 1 | E27: 1 | F27: 0 | G27: 0 | H27: =SUM(C27:G27) -> 2 | I27: 0 | J27: 0 | K27: 1 | L27: 1 | M27: 1 | N27: =SUM(I27:M27) -> 3 | O27: 0 | P27: 0 | Q27: 0 | R27: 0 | S27: 0 | T27: =SUM(O27:S27) -> 0 | U27: 0 | V27: 0 | W27: 0 | X27: 1 | Y27: 0 | Z27: =SUM(U27:Y27) -> 1 | AA27: 0 | AB27: 1 | AC27: 0 | AD27: 0 | AE27: 1 | AF27: =SUM(AA27:AE27) -> 2 | AG27: 1 | AH27: 1 | AI27: 1 | AJ27: 1 | AK27: 1 | AL27: =SUM(AG27:AK27) -> 5 | AM27: =SUM(C27:AK27) -> 21 | AN27: 07:00-17:00 | AO27: 2900 | AP27: 5 | AQ27: =IF(AR27="hr",AP27,AP27/60) -> 5 | AR27: hr | AS27: 2 | AT27: =IF(AU27="m",AS27*1,AS27*1000) -> 2000 | AU27: km | AV27: 4.7 | AY27: 18.9333 | AZ27: 98.9
A28: 26 | B28: Patara Elephant Farm | C28: 0 | D28: 1 | E28: 1 | F28: 0 | G28: 0 | H28: =SUM(C28:G28) -> 2 | I28: 0 | J28: 0 | K28: 1 | L28: 1 | M28: 1 | N28: =SUM(I28:M28) -> 3 | O28: 0 | P28: 0 | Q28: 0 | R28: 0 | S28: 0 | T28: =SUM(O28:S28) -> 0 | U28: 0 | V28: 0 | W28: 0 | X28: 1 | Y28: 0 | Z28: =SUM(U28:Y28) -> 1 | AA28: 0 | AB28: 1 | AC28: 0 | AD28: 0 | AE28: 1 | AF28: =SUM(AA28:AE28) -> 2 | AG28: 1 | AH28: 1 | AI28: 1 | AJ28: 1 | AK28: 1 | AL28: =SUM(AG28:AK28) -> 5 | AM28: =SUM(C28:AK28) -> 21 | AN28: 08:00-18:00 | AO28: 3200 | AP28: 6 | AQ28: =IF(AR28="hr",AP28,AP28/60) -> 6 | AR28: hr | AS28: 2.5 | AT28: =IF(AU28="m",AS28*1,AS28*1000) -> 2500 | AU28: km | AV28: 4.4 | AY28: 18.7781 | AZ28: 98.8163
A29: 27 | B29: Doi Inthanon National Park | C29: 0 | D29: 1 | E29: 1 | F29: 0 | G29: 0 | H29: =SUM(C29:G29) -> 2 | I29: 0 | J29: 0 | K29: 1 | L29: 1 | M29: 1 | N29: =SUM(I29:M29) -> 3 | O29: 0 | P29: 0 | Q29: 1 | R29: 0 | S29: 0 | T29: =SUM(O29:S29) -> 1 | U29: 0 | V29: 0 | W29: 0 | X29: 1 | Y29: 0 | Z29: =SUM(U29:Y29) -> 1 | AA29: 1 | AB29: 0 | AC29: 0 | AD29: 1 | AE29: 1 | AF29: =SUM(AA29:AE29) -> 3 | AG29: 1 | AH29: 1 | AI29: 1 | AJ29: 1 | AK29: 1 | AL29: =SUM(AG29:AK29) -> 5 | AM29: =SUM(C29:AK29) -> 25 | AN29: 06:00-18:00 | AO29: 50 | AP29: 4 | AQ29: =IF(AR29="hr",AP29,AP29/60) -> 4 | AR29: hr | AS29: 3 | AT29: =IF(AU29="m",AS29*1,AS29*1000) -> 3000 | AU29: km | AV29: 4.7 | AW29: 4.9 | AX29: 4.5 | AY29: 18.5886 | AZ29: 98.487
A30: 28 | B30: Queen Sirikit Botanical Garden | C30: 1 | D30: 1 | E30: 1 | F30: 0 | G30: 1 | H30: =SUM(C30:G30) -> 4 | I30: 1 | J30: 1 | K30: 1 | L30: 1 | M30: 1 | N30: =SUM(I30:M30) -> 5 | O30: 0 | P30: 0 | Q30: 1 | R30: 0 | S30: 0 | T30: =SUM(O30:S30) -> 1 | U30: 0 | V30: 1 | W30: 0 | X30: 1 | Y30: 1 | Z30: =SUM(U30:Y30) -> 3 | AA30: 1 | AB30: 0 | AC30: 0 | AD30: 1 | AE30: 1 | AF30: =SUM(AA30:AE30) -> 3 | AG30: 1 | AH30: 1 | AI30: 1 | AJ30: 0 | AK30: 1 | AL30: =SUM(AG30:AK30) -> 4 | AM30: =SUM(C30:AK30) -> 36 | AN30: 08:30-16:30 | AO30: 0 | AP30: 2 | AQ30: =IF(AR30="hr",AP30,AP30/60) -> 2 | AR30: hr | AS30: 1.5 | AT30: =IF(AU30="m",AS30*1,AS30*1000) -> 1500 | AU30: km | AV30: 4.6 | AW30: 4.7 | AX30: 4.3 | AY30: 18.9114 | AZ30: 98.8646
A31: 29 | B31: Tweechol Botanic Garden | C31: 1 | D31: 1 | E31: 1 | F31: 1 | G31: 1 | H31: =SUM(C31:G31) -> 5 | I31: 1 | J31: 1 | K31: 1 | L31: 1 | M31: 1 | N31: =SUM(I31:M31) -> 5 | O31: 1 | P31: 1 | Q31: 1 | R31: 0 | S31: 1 | T31: =SUM(O31:S31) -> 4 | U31: 1 | V31: 1 | W31: 1 | X31: 1 | Y31: 1 | Z31: =SUM(U31:Y31) -> 5 | AA31: 0 | AB31: 0 | AC31: 0 | AD31: 1 | AE31: 1 | AF31: =SUM(AA31:AE31) -> 2 | AG31: 1 | AH31: 1 | AI31: 1 | AJ31: 0 | AK31: 1 | AL31: =SUM(AG31:AK31) -> 4 | AM31: =SUM(C31:AK31) -> 46 | AN31: 08:30-17:00 | AO31: 86 | AP31: 2 | AQ31: =IF(AR31="hr",AP31,AP31/60) -> 2 | AR31: hr | AS31: 1 | AT31: =IF(AU31="m",AS31*1,AS31*1000) -> 1000 | AU31: km | AV31: 4.5 | AW31: 4.8 | AX31: 4.2 | AY31: 18.8251 | AZ31: 99.0765
A32: 30 | B32: Mon Cham | C32: 0 | D32: 1 | E32: 1 | F32: 0 | G32: 0 | H32: =SUM(C32:G32) -> 2 | I32: 0 | J32: 0 | K32: 1 | L32: 0 | M32: 1 | N32: =SUM(I32:M32) -> 2 | O32: 0 | P32: 0 | Q32: 0 | R32: 0 | S32: 0 | T32: =SUM(O32:S32) -> 0 | U32: 0 | V32: 0 | W32: 0 | X32: 0 | Y32: 0 | Z32: =SUM(U32:Y32) -> 0 | AA32: 0 | AB32: 1 | AC32: 0 | AD32: 0 | AE32: 0 | AF32: =SUM(AA32:AE32) -> 1 | AG32: 1 | AH32: 1 | AI32: 1 | AJ32: 1 | AK32: 1 | AL32: =SUM(AG32:AK32) -> 5 | AM32: =SUM(C32:AK32) -> 15 | AN32: 00:00-24:00 | AO32: 0 | AP32: 3 | AQ32: =IF(AR32="hr",AP32,AP32/60) -> 3 | AR32: hr | AS32: 2 | AT32: =IF(AU32="m",AS32*1,AS32*1000) -> 2000 | AU32: km | AV32: 4.4 | AX32: 4.1 | AY32: 18.9333 | AZ32: 98.8
A33: 31 | B33: Warorot Market (Kad Luang) | C33: 0 | D33: 0 | E33: 0 | F33: 1 | G33: 0 | H33: =SUM(C33:G33) -> 1 | I33: 0 | J33: 1 | K33: 0 | L33: 0 | M33: 0 | N33: =SUM(I33:M33) -> 1 | O33: 0 | P33: 0 | Q33: 0 | R33: 1 | S33: 0 | T33: =SUM(O33:S33) -> 1 | U33: 1 | V33: 0 | W33: 1 | X33: 1 | Y33: 0 | Z33: =SUM(U33:Y33) -> 3 | AA33: 1 | AB33: 1 | AC33: 0 | AD33: 0 | AE33: 0 | AF33: =SUM(AA33:AE33) -> 2 | AG33: 0 | AH33: 0 | AI33: 0 | AJ33: 0 | AK33: 1 | AL33: =SUM(AG33:AK33) -> 1 | AM33: =SUM(C33:AK33) -> 17 | AN33: 05:00-18:00 | AO33: 0 | AP33: 1 | AQ33: =IF(AR33="hr",AP33,AP33/60) -> 1 | AR33: hr | AS33: 500 | AT33: =IF(AU33="m",AS33*1,AS33*1000) -> 500 | AU33: m | AV33: 4.4 | AW33: 4.4 | AX33: 3.9 | AY33: 18.7881 | AZ33: 99.0003
A34: 32 | B34: Sunday Night Market (Walking Street) | C34: 1 | D34: 0 | E34: 0 | F34: 0 | G34: 0 | H34: =SUM(C34:G34) -> 1 | I34: 0 | J34: 0 | K34: 0 | L34: 0 | M34: 1 | N34: =SUM(I34:M34) -> 1 | O34: 0 | P34: 1 | Q34: 0 | R34: 1 | S34: 0 | T34: =SUM(O34:S34) -> 2 | U34: 1 | V34: 0 | W34: 1 | X34: 0 | Y34: 1 | Z34: =SUM(U34:Y34) -> 3 | AA34: 0 | AB34: 1 | AC34: 0 | AD34: 1 | AE34: 0 | AF34: =SUM(AA34:AE34) -> 2 | AG34: 1 | AH34: 1 | AI34: 0 | AJ34: 0 | AK34: 1 | AL34: =SUM(AG34:AK34) -> 3 | AM34: =SUM(C34:AK34) -> 21 | AN34: 17:00-22:30 | AO34: 0 | AP34: 2 | AQ34: =IF(AR34="hr",AP34,AP34/60) -> 2 | AR34: hr | AS34: 1.5 | AT34: =IF(AU34="m",AS34*1,AS34*1000) -> 1500 | AU34: km | AV34: 4.5 | AW34: 4.5 | AX34: 4.3 | AY34: 18.7875 | AZ34: 98.9935
A35: 33 | B35: Saturday Night Market (Wua Lai Road) | C35: 1 | D35: 0 | E35: 0 | F35: 0 | G35: 0 | H35: =SUM(C35:G35) -> 1 | I35: 0 | J35: 0 | K35: 0 | L35: 0 | M35: 1 | N35: =SUM(I35:M35) -> 1 | O35: 0 | P35: 1 | Q35: 0 | R35: 1 | S35: 0 | T35: =SUM(O35:S35) -> 2 | U35: 1 | V35: 0 | W35: 1 | X35: 0 | Y35: 1 | Z35: =SUM(U35:Y35) -> 3 | AA35: 0 | AB35: 1 | AC35: 1 | AD35: 1 | AE35: 0 | AF35: =SUM(AA35:AE35) -> 3 | AG35: 1 | AH35: 1 | AI35: 0 | AJ35: 0 | AK35: 1 | AL35: =SUM(AG35:AK35) -> 3 | AM35: =SUM(C35:AK35) -> 23 | AN35: 18:00-23:00 | AO35: 0 | AP35: 2 | AQ35: =IF(AR35="hr",AP35,AP35/60) -> 2 | AR35: hr | AS35: 1.2 | AT35: =IF(AU35="m",AS35*1,AS35*1000) -> 1200 | AU35: km | AV35: 4.4 | AW35: 4.5 | AX35: 4 | AY35: 18.7815 | AZ35: 98.9875
A36: 34 | B36: Chiang Mai Gate Market | C36: 1 | D36: 0 | E36: 0 | F36: 0 | G36: 1 | H36: =SUM(C36:G36) -> 2 | I36: 0 | J36: 1 | K36: 1 | L36: 1 | M36: 1 | N36: =SUM(I36:M36) -> 4 | O36: 0 | P36: 1 | Q36: 0 | R36: 1 | S36: 0 | T36: =SUM(O36:S36) -> 2 | U36: 1 | V36: 0 | W36: 1 | X36: 0 | Y36: 0 | Z36: =SUM(U36:Y36) -> 2 | AA36: 0 | AB36: 1 | AC36: 0 | AD36: 1 | AE36: 0 | AF36: =SUM(AA36:AE36) -> 2 | AG36: 1 | AH36: 1 | AI36: 0 | AJ36: 0 | AK36: 1 | AL36: =SUM(AG36:AK36) -> 3 | AM36: =SUM(C36:AK36) -> 27 | AN36: 04:00-24:00 | AO36: 0 | AP36: 1 | AQ36: =IF(AR36="hr",AP36,AP36/60) -> 1 | AR36: hr | AS36: 400 | AT36: =IF(AU36="m",AS36*1,AS36*1000) -> 400 | AU36: m | AV36: 4.4 | AW36: 4.6 | AY36: 18.7819 | AZ36: 98.9907
A37: 35 | B37: Ton Lamyai Flower Market | C37: 0 | D37: 1 | E37: 1 | F37: 1 | G37: 1 | H37: =SUM(C37:G37) -> 4 | I37: 0 | J37: 1 | K37: 1 | L37: 1 | M37: 1 | N37: =SUM(I37:M37) -> 4 | O37: 0 | P37: 1 | Q37: 0 | R37: 1 | S37: 0 | T37: =SUM(O37:S37) -> 2 | U37: 1 | V37: 0 | W37: 1 | X37: 1 | Y37: 0 | Z37: =SUM(U37:Y37) -> 3 | AA37: 0 | AB37: 1 | AC37: 0 | AD37: 1 | AE37: 0 | AF37: =SUM(AA37:AE37) -> 2 | AG37: 1 | AH37: 1 | AI37: 0 | AJ37: 0 | AK37: 1 | AL37: =SUM(AG37:AK37) -> 3 | AM37: =SUM(C37:AK37) -> 33 | AN37: 05:00-17:00 | AO37: 0 | AP37: 1 | AQ37: =IF(AR37="hr",AP37,AP37/60) -> 1 | AR37: hr | AS37: 400 | AT37: =IF(AU37="m",AS37*1,AS37*1000) -> 400 | AU37: m | AV37: 4.3 | AX37: 3.5 | AY37: 18.7879 | AZ37: 99.0008
A38: 36 | B38: Baan Tawai Handicraft Village | C38: 0 | D38: 1 | E38: 1 | F38: 0 | G38: 1 | H38: =SUM(C38:G38) -> 3 | I38: 1 | J38: 1 | K38: 1 | L38: 1 | M38: 1 | N38: =SUM(I38:M38) -> 5 | O38: 0 | P38: 1 | Q38: 1 | R38: 0 | S38: 0 | T38: =SUM(O38:S38) -> 2 | U38: 1 | V38: 1 | W38: 1 | X38: 1 | Y38: 0 | Z38: =SUM(U38:Y38) -> 4 | AA38: 1 | AB38: 1 | AC38: 1 | AD38: 1 | AE38: 1 | AF38: =SUM(AA38:AE38) -> 5 | AG38: 1 | AH38: 1 | AI38: 0 | AJ38: 0 | AK38: 1 | AL38: =SUM(AG38:AK38) -> 3 | AM38: =SUM(C38:AK38) -> 41 | AN38: 09:00-17:00 | AO38: 0 | AP38: 1.5 | AQ38: =IF(AR38="hr",AP38,AP38/60) -> 1.5 | AR38: hr | AS38: 700 | AT38: =IF(AU38="m",AS38*1,AS38*1000) -> 700 | AU38: m | AV38: 4.6 | AW38: 4.6 | AX38: 3.4 | AY38: 18.6985 | AZ38: 98.893
A39: 37 | B39: Bo Sang Umbrella Village | C39: 0 | D39: 1 | E39: 1 | F39: 0 | G39: 1 | H39: =SUM(C39:G39) -> 3 | I39: 1 | J39: 1 | K39: 1 | L39: 1 | M39: 1 | N39: =SUM(I39:M39) -> 5 | O39: 1 | P39: 1 | Q39: 1 | R39: 0 | S39: 0 | T39: =SUM(O39:S39) -> 3 | U39: 1 | V39: 1 | W39: 1 | X39: 1 | Y39: 1 | Z39: =SUM(U39:Y39) -> 5 | AA39: 0 | AB39: 1 | AC39: 1 | AD39: 1 | AE39: 1 | AF39: =SUM(AA39:AE39) -> 4 | AG39: 1 | AH39: 1 | AI39: 0 | AJ39: 0 | AK39: 1 | AL39: =SUM(AG39:AK39) -> 3 | AM39: =SUM(C39:AK39) -> 43 | AN39: 08:00-17:00 | AO39: 0 | AP39: 1 | AQ39: =IF(AR39="hr",AP39,AP39/60) -> 1 | AR39: hr | AS39: 500 | AT39: =IF(AU39="m",AS39*1,AS39*1000) -> 500 | AU39: m | AV39: 4.2 | AW39: 4.1 | AX39: 4.2 | AY39: 18.761 | AZ39: 99.116
A40: 38 | B40: San Kamphaeng Silk Village | C40: 0 | D40: 1 | E40: 1 | F40: 0 | G40: 1 | H40: =SUM(C40:G40) -> 3 | I40: 1 | J40: 1 | K40: 1 | L40: 1 | M40: 1 | N40: =SUM(I40:M40) -> 5 | O40: 1 | P40: 1 | Q40: 1 | R40: 0 | S40: 0 | T40: =SUM(O40:S40) -> 3 | U40: 1 | V40: 1 | W40: 1 | X40: 1 | Y40: 1 | Z40: =SUM(U40:Y40) -> 5 | AA40: 0 | AB40: 1 | AC40: 1 | AD40: 1 | AE40: 1 | AF40: =SUM(AA40:AE40) -> 4 | AG40: 1 | AH40: 1 | AI40: 0 | AJ40: 0 | AK40: 1 | AL40: =SUM(AG40:AK40) -> 3 | AM40: =SUM(C40:AK40) -> 43 | AN40: 8:30-17:30 | AO40: 0 | AP40: 1.5 | AQ40: =IF(AR40="hr",AP40,AP40/60) -> 1.5 | AR40: hr | AS40: 800 | AT40: =IF(AU40="m",AS40*1,AS40*1000) -> 800 | AU40: m | AV40: 4 | AY40: 18.729 | AZ40: 99.147
...

Sheet LaLong
A1: No | B1: Latitude | C1: Longitude
A2: 0 | B2: 18.805289 | C2: 98.959698
A3: 1 | B3: 18.805 | C3: 98.9216
A4: 2 | B4: 18.787 | C4: 98.9866
A5: 3 | B5: 18.7885 | C5: 98.982
A6: 4 | B6: 18.7827 | C6: 98.9521
A7: 5 | B7: 18.7938 | C7: 98.9893
A8: 6 | B8: 18.7882 | C8: 98.9678
A9: 7 | B9: 18.786 | C9: 98.9826
A10: 8 | B10: 18.7787 | C10: 98.9837
A11: 9 | B11: 18.788 | C11: 98.9983
A12: 10 | B12: 18.7924 | C12: 99.0034
A13: 11 | B13: 18.7889 | C13: 98.9908
... A52: 50 | B52: 18.865 | C52: 99.343

Sheet Distance
A1: No | B1: 0 | C1: 1 | D1: 2 | E1: 3 | F1: 4 | G1: 5 | H1: 6 | I1: 7 | J1: 8 | K1: 9 | L1: 10 | M1: 11 | N1: 12 | O1: 13 | P1: 14 | Q1: 15 | R1: 16 | S1: 17 | T1: 18 | U1: 19 | V1: 20 | W1: 21 | X1: 22 | Y1: 23 | Z1: 24 | AA1: 25 | AB1: 26 | AC1: 27 | AD1: 28 | AE1: 29 | AF1: 30 | AG1: 31 | AH1: 32 | AI1: 33 | AJ1: 34 | AK1: 35 | AL1: 36 | AM1: 37 | AN1: 38 | AO1: 39 | AP1: 40 | AQ1: 41 | AR1: 42 | AS1: 43 | AT1: 44 | AU1: 45 | AV1: 46 | AW1: 47 | AX1: 48 | AY1: 49 | AZ1: 50
A2: 0 | B2: 9999 | C2: 12.384 | D2: 5.709 | E2: 4.611 | F2: 4.139 | G2: 4.699 | H2: 3.354 | I2: 5.163 | J2: 6.761 | K2: 5.99 | L2: 8.489 | M2: 5.396 | N2: 5.015 | O2: 3.189 | P2: 4.148 | Q2: 17.853 | R2: 6.772 | S2: 5.126 | T2: 2.431 | U2: 21.784 | V2: 4.148 | W2: 16.8 | X2: 1.673 | Y2: 11.654 | Z2: 16.458 | AA2: 22.837 | AB2: 29.996 | AC2: 108.637 | AD2: 27.547 | AE2: 18.023 | AF2: 39.632 | AG2: 6.256 | AH2: 5.42 | AI2: 6.095 | AJ2: 6.604 | AK2: 6.205 | AL2: 17.636 | AM2: 20.938 | AN2: 24.774 | AO2: 1.765 | AP2: 5.07 | AQ2: 11.033 | AR2: 10.031 | AS2: 12.51 | AT2: 31.446 | AU2: 109.226 | AV2: 6.977 | AW2: 2.393 | AX2: 39.08 | AY2: 25.18 | AZ2: 52.208
A3: 1 | B3: 12.986 | C3: 9999 | D3: 16.81 | E3: 16.267 | F3: 15.795 | G3: 16.355 | H3: 15.01 | I3: 16.819 | J3: 18.417 | K3: 17.646 | L3: 20.145 | M3: 17.052 | N3: 16.789 | O3: 14.845 | P3: 15.804 | Q3: 29.509 | R3: 18.428 | S3: 16.782 | T3: 14.087 | U3: 33.44 | V3: 15.804 | W3: 28.456 | X3: 11.196 | Y3: 23.31 | Z3: 28.114 | AA3: 32.902 | AB3: 41.652 | AC3: 120.293 | AD3: 39.203 | AE3: 29.679 | AF3: 51.288 | AG3: 17.912 | AH3: 17.076 | AI3: 17.751 | AJ3: 18.26 | AK3: 20.524 | AL3: 29.292 | AM3: 32.594 | AN3: 36.43 | AO3: 13.421 | AP3: 16.726 | AQ3: 22.689 | AR3: 21.687 | AS3: 0.511 | AT3: 43.102 | AU3: 120.882 | AV3: 9.702 | AW3: 11.916 | AX3: 50.181 | AY3: 36.836 | AZ3: 63.864
A4: 2 | B4: 4.321 | C4: 16.633 | D4: 9999 | E4: 0.665 | F4: 5.267 | G4: 1.121 | H4: 2.881 | I4: 1.217 | J4: 2.183 | K4: 2.477 | L4: 3.235 | M4: 0.668 | N4: 0.632 | O4: 4.91 | P4: 5.639 | Q4: 13.156 | R4: 2.578 | S4: 0.699 | T4: 3.268 | U4: 23.056 | V4: 5.639 | W4: 16.427 | X4: 5.922 | Y4: 13.328 | Z4: 17.73 | AA4: 22.518 | AB4: 30.004 | AC4: 102.984 | AD4: 28.819 | AE4: 15.236 | AF4: 40.904 | AG4: 3.095 | AH4: 1.415 | AI4: 1.213 | AJ4: 1.157 | AK4: 3.044 | AL4: 17.61 | AM4: 16.241 | AN4: 25.489 | AO4: 3.317 | AP4: 3.144 | AQ4: 12.707 | AR4: 13.065 | AS4: 16.759 | AT4: 31.42 | AU4: 110.354 | AV4: 11.226 | AW4: 6.642 | AX4: 39.797 | AY4: 26.452 | AZ4: 49.421
A5: 3 | B5: 3.762 | C5: 16.074 | D5: 0.649 | E5: 9999 | F5: 4.869 | G5: 1.497 | H5: 2.483 | I5: 0.658 | J5: 2.105 | K5: 2.86 | L5: 3.691 | M5: 1.051 | N5: 1.015 | O5: 4.351 | P5: 5.788 | Q5: 17.783 | R5: 2.961 | S5: 0.837 | T5: 2.709 | U5: 23.205 | V5: 5.788 | W5: 17.962 | X5: 5.363 | Y5: 12.769 | Z5: 17.879 | AA5: 22.667 | AB5: 29.445 | AC5: 102.425 | AD5: 28.968 | AE5: 15.619 | AF5: 41.053 | AG5: 3.478 | AH5: 1.798 | AI5: 1.439 | AJ5: 1.54 | AK5: 3.427 | AL5: 17.051 | AM5: 20.868 | AN5: 24.93 | AO5: 2.758 | AP5: 3.293 | AQ5: 12.148 | AR5: 13.044 | AS5: 16.2 | AT5: 30.861 | AU5: 103.014 | AV5: 10.667 | AW5: 6.083 | AX5: 39.946 | AY5: 26.601 | AZ5: 49.804
A6: 4 | B6: 3.537 | C6: 15.849 | D6: 5.262 | E6: 4.719 | F6: 9999 | G6: 6.214 | H6: 2.747 | I6: 5.27 | J6: 6.652 | K6: 7.505 | L6: 7.475 | M6: 5.664 | N6: 5.331 | O6: 5.977 | P6: 6.936 | Q6: 20.641 | R6: 8.05 | S6: 5.234 | T6: 3.599 | U6: 24.572 | V6: 6.936 | W6: 19.588 | X6: 4.743 | Y6: 9.298 | Z6: 19.246 | AA6: 24.034 | AB6: 27.64 | AC6: 106.281 | AD6: 30.335 | AE6: 20.811 | AF6: 42.42 | AG6: 7.771 | AH6: 6.935 | AI6: 5.986 | AJ6: 6.495 | AK6: 7.72 | AL6: 15.28 | AM6: 23.726 | AN6: 32.194 | AO6: 3.39 | AP6: 7.858 | AQ6: 8.677 | AR6: 12.819 | AS6: 15.975 | AT6: 29.09 | AU6: 106.87 | AV6: 10.442 | AW6: 3.561 | AX6: 41.313 | AY6: 27.968 | AZ6: 54.996
A7: 5 | B7: 4.298 | C7: 16.61 | D7: 1.121 | E7: 1.908 | F7: 6.359 | G7: 9999 | H7: 3.973 | I7: 2.46 | J7: 2.437 | K7: 2.098 | L7: 2.227 | M7: 0.612 | N7: 0.561 | O7: 4.887 | P7: 5.134 | Q7: 16.975 | R7: 2.691 | S7: 0.79 | T7: 3.245 | U7: 22.551 | V7: 5.134 | W7: 15.922 | X7: 5.899 | Y7: 13.874 | Z7: 17.225 | AA7: 22.013 | AB7: 31.648 | AC7: 104.628 | AD7: 28.314 | AE7: 14.228 | AF7: 40.399 | AG7: 2.716 | AH7: 1.528 | AI7: 1.86 | AJ7: 1.411 | AK7: 2.545 | AL7: 19.254 | AM7: 20.06 | AN7: 23.896 | AO7: 3.294 | AP7: 2.639 | AQ7: 13.253 | AR7: 12.56 | AS7: 16.736 | AT7: 33.064 | AU7: 105.217 | AV7: 11.203 | AW7: 6.619 | AX7: 39.292 | AY7: 25.947 | AZ7: 48.413
A8: 6 | B8: 2.743 | C8: 15.055 | D8: 2.798 | E8: 2.255 | F8: 2.669 | G8: 3.75 | H8: 9999 | I8: 2.806 | J8: 4.188 | K8: 5.041 | L8: 5.011 | M8: 3.2 | N8: 2.867 | O8: 3.536 | P8: 6.142 | Q8: 18.2 | R8: 5.586 | S8: 2.77 | T8: 1.135 | U8: 23.778 | V8: 6.142 | W8: 17.147 | X8: 4.344 | Y8: 10.184 | Z8: 18.452 | AA8: 23.24 | AB8: 28.526 | AC8: 107.167 | AD8: 29.541 | AE8: 18.37 | AF8: 41.626 | AG8: 5.307 | AH8: 4.471 | AI8: 3.522 | AJ8: 4.031 | AK8: 5.256 | AL8: 16.166 | AM8: 21.285 | AN8: 25.121 | AO8: 1.943 | AP8: 4.344 | AQ8: 9.563 | AR8: 12.025 | AS8: 15.181 | AT8: 29.976 | AU8: 107.756 | AV8: 9.648 | AW8: 5.064 | AX8: 40.519 | AY8: 28.205 | AZ8: 52.555
A9: 7 | B9: 4.029 | C9: 16.341 | D9: 0.916 | E9: 0.373 | F9: 4.769 | G9: 1.764 | H9: 2.383 | I9: 9999 | J9: 1.846 | K9: 3.127 | L9: 3.885 | M9: 1.318 | N9: 1.282 | O9: 4.618 | P9: 6.055 | Q9: 17.524 | R9: 3.244 | S9: 1.1 | T9: 2.797 | U9: 23.472 | V9: 6.055 | W9: 18.229 | X9: 5.63 | Y9: 12.51 | Z9: 18.146 | AA9: 22.934 | AB9: 29.186 | AC9: 102.166 | AD9: 29.235 | AE9: 15.886 | AF9: 41.32 | AG9: 4.051 | AH9: 2.065 | AI9: 1.18 | AJ9: 1.689 | AK9: 4 | AL9: 16.792 | AM9: 20.609 | AN9: 24.671 | AO9: 3.025 | AP9: 3.56 | AQ9: 11.356 | AR9: 13.311 | AS9: 16.467 | AT9: 30.602 | AU9: 102.755 | AV9: 10.934 | AW9: 6.35 | AX9: 40.213 | AY9: 26.868 | AZ9: 50.071
A10: 8 | B10: 4.78 | C10: 17.092 | D10: 2.285 | E10: 1.544 | F10: 5.253 | G10: 2.932 | H10: 2.867 | I10: 1.472 | J10: 9999 | K10: 3.429 | L10: 4.652 | M10: 2.479 | N10: 2.443 | O10: 5.369 | P10: 7.434 | Q10: 16.153 | R10: 3.194 | S10: 2.51 | T10: 3.281 | U10: 24.851 | V10: 7.434 | W10: 18.98 | X10: 6.381 | Y10: 11.193 | Z10: 19.525 | AA10: 24.313 | AB10: 27.869 | AC10: 100.849 | AD10: 30.614 | AE10: 20.101 | AF10: 42.699 | AG10: 4.001 | AH10: 3.016 | AI10: 1.13 | AJ10: 1.639 | AK10: 3.95 | AL10: 15.475 | AM10: 19.238 | AN10: 23.3 | AO10: 3.776 | AP10: 4.939 | AQ10: 10.572 | AR10: 14.062 | AS10: 17.218 | AT10: 29.285 | AU10: 101.438 | AV10: 11.685 | AW10: 7.101 | AX10: 41.592 | AY10: 28.247 | AZ10: 54.388
A11: 9 | B11: 6.765 | C11: 19.077 | D11: 1.928 | E11: 2.327 | F11: 7.238 | G11: 2.494 | H11: 4.852 | I11: 2.879 | J11: 2.376 | K11: 9999 | L11: 2.569 | M11: 1.636 | N11: 1.984 | O11: 7.354 | P11: 7.256 | Q11: 11.987 | R11: 1.726 | S11: 2.153 | T11: 5.266 | U11: 24.673 | V11: 7.256 | W11: 14.549 | X11: 8.366 | Y11: 14.146 | Z11: 19.347 | AA11: 24.135 | AB11: 30.822 | AC11: 103.802 | AD11: 31.472 | AE11: 14.067 | AF11: 42.521 | AG11: 1.926 | AH11: 0.563 | AI11: 2.305 | AJ11: 1.655 | AK11: 1.875 | AL11: 18.428 | AM11: 15.072 | AN11: 18.908 | AO11: 5.761 | AP11: 3.966 | AQ11: 13.525 | AR11: 14.682 | AS11: 19.203 | AT11: 32.238 | AU11: 104.391 | AV11: 13.67 | AW11: 9.086 | AX11: 37.141 | AY11: 28.069 | AZ11: 48.252
A12: 10 | B12: 7.836 | C12: 20.148 | D12: 3.25 | E12: 3.649 | F12: 8.57 | G12: 2.409 | H12: 6.174 | I12: 4.201 | J12: 3.698 | K12: 1.374 | L12: 9999 | M12: 2.958 | N12: 2.284 | O12: 7.728 | P12: 6.891 | Q12: 10.649 | R12: 1.66 | S12: 3.278 | T12: 7.587 | U12: 24.308 | V12: 6.891 | W12: 13.433 | X12: 9.437 | Y12: 19.803 | Z12: 18.982 | AA12: 23.77 | AB12: 32.144 | AC12: 105.124 | AD12: 30.071 | AE12: 12.559 | AF12: 42.156 | AG12: 1.144 | AH12: 1.885 | AI12: 3.627 | AJ12: 2.977 | AK12: 1.093 | AL12: 19.75 | AM12: 13.734 | AN12: 17.57 | AO12: 6.931 | AP12: 3.465 | AQ12: 14.796 | AR12: 17.416 | AS12: 20.274 | AT12: 33.56 | AU12: 105.713 | AV12: 14.463 | AW12: 10.157 | AX12: 36.025 | AY12: 27.704 | AZ12: 46.744
A13: 11 | B13: 4.786 | C13: 17.098 | D13: 0.668 | E13: 1.067 | F13: 5.669 | G13: 0.612 | H13: 3.283 | I13: 1.619 | J13: 1.957 | K13: 2.185 | L13: 2.943 | M13: 9999 | N13: 0.457 | O13: 5.375 | P13: 5.622 | Q13: 12.864 | R13: 2.286 | S13: 0.682 | T13: 3.733 | U13: 24.075 | V13: 5.622 | W13: 15.388 | X13: 6.387 | Y13: 13.727 | Z13: 17.713 | AA13: 22.501 | AB13: 30.403 | AC13: 103.383 | AD13: 28.802 | AE13: 14.944 | AF13: 40.887 | AG13: 2.803 | AH13: 1.123 | AI13: 1.407 | AJ13: 0.931 | AK13: 2.752 | AL13: 18.009 | AM13: 15.949 | AN13: 19.785 | AO13: 3.782 | AP13: 3.31 | AQ13: 13.106 | AR13: 13.113 | AS13: 17.224 | AT13: 31.819 | AU13: 103.972 | AV13: 11.691 | AW13: 7.107 | AX13: 39.78 | AY13: 26.435 | AZ13: 49.129
... A52: 50 | B52: 51.674 | C52: 63.986 | D52: 49.925 | E52: 50.138 | F52: 54.008 | G52: 48.602 | H52: 52.562 | I52: 50.69 | J52: 50.373 | K52: 48.049 | L52: 46.751 | M52: 48.528 | N52: 48.477 | O52: 51.566 | P52: 50.729 | Q52: 37.699 | R52: 48.335 | S52: 49.471 | T52: 51.425 | U52: 64.096 | V52: 50.729 | W52: 51.06 | X52: 53.275 | Y52: 64.528 | Z52: 58.77 | AA52: 63.558 | AB52: 81.751 | AC52: 154.731 | AD52: 69.859 | AE52: 39.471 | AF52: 81.944 | AG52: 47.819 | AH52: 48.56 | AI52: 50.302 | AJ52: 49.652 | AK52: 47.768 | AL52: 70.51 | AM52: 38.233 | AN52: 31.882 | AO52: 50.769 | AP52: 48.417 | AQ52: 63.907 | AR52: 54.726 | AS52: 64.112 | AT52: 84.32 | AU52: 155.32 | AV52: 58.579 | AW52: 53.995 | AX52: 73.652 | AY52: 67.492 | AZ52: 9999

Sheet Input
A1: Locations | B1: S | C1: TW_min | D1: TW_max | E1: R | F1: Safety | G1: Comf | H1: Acess | I1: Culture | J1: Walking | K1: Fee | L1: Pathway | M1: Scen
A2: 0 | B2: 0 | C2: 0 | D2: 24 | E2: 0 | F2: 0 | G2: 0 | H2: 0 | I2: 0 | J2: 0 | K2: 0 | L2: 0 | M2: 0
A3: 1 | B3: =AVERAGE(Data_Adj!AV3:AX3) -> 4.6333333 | C3: 6 | D3: 20 | E3: 1.5 | F3: =Data_Adj!H3 -> 3 | G3: =Data_Adj!N3 -> 5 | H3: =Data_Adj!T3 -> 2 | I3: =Data_Adj!AF3 -> 3 | J3: 500 | K3: =Data_Adj!AO3 -> 20 | L3: =Data_Adj!Z3 -> 3 | M3: =Data_Adj!AL3 -> 5
A4: 2 | B4: =AVERAGE(Data_Adj!AV4:AX4) -> 4.6666667 | C4: 5 | D4: 22 | E4: 1 | F4: =Data_Adj!H4 -> 5 | G4: =Data_Adj!N4 -> 5 | H4: =Data_Adj!T4 -> 5 | I4: =Data_Adj!AF4 -> 4 | J4: 300 | K4: =Data_Adj!AO4 -> 0 | L4: =Data_Adj!Z4 -> 5 | M4: =Data_Adj!AL4 -> 3
A5: 3 | B5: =AVERAGE(Data_Adj!AV5:AX5) -> 4.6666667 | C5: 5.5 | D5: 19.5 | E5: 1 | F5: =Data_Adj!H5 -> 5 | G5: =Data_Adj!N5 -> 5 | H5: =Data_Adj!T5 -> 5 | I5: =Data_Adj!AF5 -> 4 | J5: 250 | K5: =Data_Adj!AO5 -> 0 | L5: =Data_Adj!Z5 -> 5 | M5: =Data_Adj!AL5 -> 3
